<?xml version="1.0" ?>
<!-- =================================================================================== -->
<!-- |    This document was autogenerated by xacro from /home/mast/catkin_ws/src/psr/robutler_description/urdf/robutler.urdf.xacro | -->
<!-- |    EDITING THIS FILE BY HAND IS NOT RECOMMENDED                                 | -->
<!-- =================================================================================== -->
<robot name="turtlebot3_waffle_pi">
    <!-- Init colour -->
    <material name="black">
        <color rgba="0.0 0.0 0.0 1.0" />
    </material>
    <material name="dark">
        <color rgba="0.3 0.3 0.3 1.0" />
    </material>
    <material name="light_black">
        <color rgba="0.4 0.4 0.4 1.0" />
    </material>
    <material name="blue">
        <color rgba="0.0 0.0 0.8 1.0" />
    </material>
    <material name="green">
        <color rgba="0.0 0.8 0.0 1.0" />
    </material>
    <material name="grey">
        <color rgba="0.5 0.5 0.5 1.0" />
    </material>
    <material name="orange">
        <color rgba="1.0 0.4235294117647059 0.0392156862745098 1.0" />
    </material>
    <material name="brown">
        <color rgba="0.8705882352941177 0.8117647058823529 0.7647058823529411 1.0" />
    </material>
    <material name="red">
        <color rgba="0.8 0.0 0.0 1.0" />
    </material>
    <material name="white">
        <color rgba="1.0 1.0 1.0 1.0" />
    </material>
    <material name="yellow">
        <color rgba="1.0 1.0 0.0 1.0" />
    </material>
    <gazebo reference="base_link">
        <material>Gazebo/DarkGrey</material>
        <plugin name="gazebo_ros_control">
            <robotNamespace>/</robotNamespace>
        </plugin>
    </gazebo>
    <gazebo reference="wheel_left_link">
        <mu1>0.1</mu1>
        <mu2>0.1</mu2>
        <kp>500000.0</kp>
        <kd>10.0</kd>
        <minDepth>0.001</minDepth>
        <maxVel>0.1</maxVel>
        <fdir1>1 0 0</fdir1>
        <!-- <material>Gazebo/FlatBlack</material> -->
        <material>Gazebo/Yellow</material>
    </gazebo>
    <gazebo reference="wheel_right_link">
        <mu1>0.1</mu1>
        <mu2>0.1</mu2>
        <kp>500000.0</kp>
        <kd>10.0</kd>
        <minDepth>0.001</minDepth>
        <maxVel>0.1</maxVel>
        <fdir1>1 0 0</fdir1>
        <!-- <material>Gazebo/FlatBlack</material> -->
        <material>Gazebo/Yellow</material>
    </gazebo>
    <gazebo reference="caster_back_right_link">
        <mu1>0.1</mu1>
        <mu2>0.1</mu2>
        <kp>1000000.0</kp>
        <kd>100.0</kd>
        <minDepth>0.001</minDepth>
        <maxVel>1.0</maxVel>
        <material>Gazebo/FlatBlack</material>
    </gazebo>
    <gazebo reference="caster_back_left_link">
        <mu1>0.1</mu1>
        <mu2>0.1</mu2>
        <kp>1000000.0</kp>
        <kd>100.0</kd>
        <minDepth>0.001</minDepth>
        <maxVel>1.0</maxVel>
        <material>Gazebo/FlatBlack</material>
    </gazebo>
    <gazebo reference="imu_link">
        <sensor name="imu" type="imu">
            <always_on>true</always_on>
            <visualize>false</visualize>
        </sensor>
        <material>Gazebo/Grey</material>
    </gazebo>
    <gazebo>
        <plugin filename="libgazebo_ros_diff_drive.so" name="turtlebot3_waffle_pi_controller">
            <commandTopic>cmd_vel</commandTopic>
            <odometryTopic>odom</odometryTopic>
            <odometryFrame>odom</odometryFrame>
            <odometrySource>world</odometrySource>
            <publishOdomTF>true</publishOdomTF>
            <robotBaseFrame>base_footprint</robotBaseFrame>
            <publishWheelTF>false</publishWheelTF>
            <publishTf>true</publishTf>
            <publishWheelJointState>true</publishWheelJointState>
            <legacyMode>false</legacyMode>
            <updateRate>30</updateRate>
            <leftJoint>wheel_left_joint</leftJoint>
            <rightJoint>wheel_right_joint</rightJoint>
            <wheelSeparation>0.287</wheelSeparation>
            <wheelDiameter>0.066</wheelDiameter>
            <wheelAcceleration>1</wheelAcceleration>
            <wheelTorque>10</wheelTorque>
            <rosDebugLevel>na</rosDebugLevel>
        </plugin>
    </gazebo>
    <gazebo>
        <plugin filename="libgazebo_ros_imu.so" name="imu_plugin">
            <alwaysOn>true</alwaysOn>
            <bodyName>imu_link</bodyName>
            <frameName>imu_link</frameName>
            <topicName>imu</topicName>
            <serviceName>imu_service</serviceName>
            <gaussianNoise>0.0</gaussianNoise>
            <updateRate>0</updateRate>
            <imu>
                <noise>
                    <type>gaussian</type>
                    <rate>
                        <mean>0.0</mean>
                        <stddev>2e-4</stddev>
                        <bias_mean>0.0000075</bias_mean>
                        <bias_stddev>0.0000008</bias_stddev>
                    </rate>
                    <accel>
                        <mean>0.0</mean>
                        <stddev>1.7e-2</stddev>
                        <bias_mean>0.1</bias_mean>
                        <bias_stddev>0.001</bias_stddev>
                    </accel>
                </noise>
            </imu>
        </plugin>
    </gazebo>
    <gazebo reference="base_scan">
        <material>Gazebo/FlatBlack</material>
        <sensor name="lds_lfcd_sensor" type="ray">
            <pose>0 0 0 0 0 0</pose>
            <visualize>false</visualize>
            <update_rate>5</update_rate>
            <ray>
                <scan>
                    <horizontal>
                        <samples>360</samples>
                        <resolution>1</resolution>
                        <min_angle>0.0</min_angle>
                        <max_angle>6.28319</max_angle>
                    </horizontal>
                </scan>
                <range>
                    <min>0.120</min>
                    <max>3.5</max>
                    <resolution>0.015</resolution>
                </range>
                <noise>
                    <type>gaussian</type>
                    <mean>0.0</mean>
                    <stddev>0.01</stddev>
                </noise>
            </ray>
            <plugin filename="libgazebo_ros_laser.so" name="gazebo_ros_lds_lfcd_controller">
                <topicName>scan</topicName>
                <frameName>base_scan</frameName>
            </plugin>
        </sensor>
    </gazebo>
    <!--link : https://www.raspberrypi.org/documentation/hardware/camera/-->
    <gazebo reference="camera_rgb_frame">
        <sensor name="Pi Camera" type="camera">
            <always_on>true</always_on>
            <visualize>false</visualize>
            <camera>
                <horizontal_fov>1.085595</horizontal_fov>
                <image>
                    <width>640</width>
                    <height>480</height>
                    <format>R8G8B8</format>
                </image>
                <clip>
                    <near>0.03</near>
                    <far>100</far>
                </clip>
            </camera>
            <plugin filename="libgazebo_ros_camera.so" name="camera_controller">
                <alwaysOn>true</alwaysOn>
                <updateRate>30.0</updateRate>
                <cameraName>camera</cameraName>
                <frameName>camera_rgb_optical_frame</frameName>
                <imageTopicName>rgb/image_raw</imageTopicName>
                <cameraInfoTopicName>rgb/camera_info</cameraInfoTopicName>
                <hackBaseline>0.07</hackBaseline>
                <distortionK1>0.0</distortionK1>
                <distortionK2>0.0</distortionK2>
                <distortionK3>0.0</distortionK3>
                <distortionT1>0.0</distortionT1>
                <distortionT2>0.0</distortionT2>
            </plugin>
        </sensor>
    </gazebo>
    <gazebo>
        <plugin filename="libgazebo_ros_control.so" name="gazebo_ros_control">
            <robotNamespace>/moveo_urdf</robotNamespace>
            <robotSimType>gazebo_ros_control/DefaultRobotHWSim</robotSimType>
            <legacyModeNS>true</legacyModeNS>
        </plugin>
    </gazebo>
    <transmission name="trans1">
        <type>transmission_interface/SimpleTransmission</type>
        <joint name="Joint_1">
            <hardwareInterface>hardware_interface/EffortJointInterface</hardwareInterface>
        </joint>
        <actuator name="motor1">
            <mechanicalReduction>1</mechanicalReduction>
            <hardwareInterface>hardware_interface/EffortJointInterface</hardwareInterface>
        </actuator>
    </transmission>
    <transmission name="trans2">
        <type>transmission_interface/SimpleTransmission</type>
        <joint name="Joint_2">
            <hardwareInterface>hardware_interface/EffortJointInterface</hardwareInterface>
        </joint>
        <actuator name="motor2">
            <mechanicalReduction>1</mechanicalReduction>
            <hardwareInterface>hardware_interface/EffortJointInterface</hardwareInterface>
        </actuator>
    </transmission>
    <transmission name="trans3">
        <type>transmission_interface/SimpleTransmission</type>
        <joint name="Joint_3">
            <hardwareInterface>hardware_interface/EffortJointInterface</hardwareInterface>
        </joint>
        <actuator name="motor3">
            <mechanicalReduction>1</mechanicalReduction>
            <hardwareInterface>hardware_interface/EffortJointInterface</hardwareInterface>
        </actuator>
    </transmission>
    <transmission name="trans4">
        <type>transmission_interface/SimpleTransmission</type>
        <joint name="Joint_4">
            <hardwareInterface>hardware_interface/EffortJointInterface</hardwareInterface>
        </joint>
        <actuator name="motor4">
            <mechanicalReduction>1</mechanicalReduction>
            <hardwareInterface>hardware_interface/EffortJointInterface</hardwareInterface>
        </actuator>
    </transmission>
    <transmission name="trans5">
        <type>transmission_interface/SimpleTransmission</type>
        <joint name="Joint_5">
            <hardwareInterface>hardware_interface/EffortJointInterface</hardwareInterface>
        </joint>
        <actuator name="motor5">
            <mechanicalReduction>1</mechanicalReduction>
            <hardwareInterface>hardware_interface/EffortJointInterface</hardwareInterface>
        </actuator>
    </transmission>
    <transmission name="trans6">
        <type>transmission_interface/SimpleTransmission</type>
        <joint name="Gripper_Servo_Gear_Joint">
            <hardwareInterface>hardware_interface/EffortJointInterface</hardwareInterface>
        </joint>
        <actuator name="motor6">
            <mechanicalReduction>1</mechanicalReduction>
            <hardwareInterface>hardware_interface/EffortJointInterface</hardwareInterface>
        </actuator>
    </transmission>
    <transmission name="trans7">
        <type>transmission_interface/SimpleTransmission</type>
        <joint name="Gripper_Idol_Gear_Joint">
            <hardwareInterface>hardware_interface/EffortJointInterface</hardwareInterface>
        </joint>
        <actuator name="motor7">
            <mechanicalReduction>1</mechanicalReduction>
            <hardwareInterface>hardware_interface/EffortJointInterface</hardwareInterface>
        </actuator>
    </transmission>
    <gazebo>
        <plugin filename="libroboticsgroup_gazebo_mimic_joint_plugin.so" name="mimic_moveo_1">
            <joint>Gripper_Servo_Gear_Joint</joint>
            <mimicJoint>Tip_Gripper_Servo_Joint</mimicJoint>
            <multiplier>1.0</multiplier>
            <offset>0.0</offset>
            <hasPID />
        </plugin>
        <plugin filename="libroboticsgroup_gazebo_mimic_joint_plugin.so" name="mimic_moveo_2">
            <joint>Gripper_Idol_Gear_Joint</joint>
            <mimicJoint>Tip_Gripper_Idol_Joint</mimicJoint>
            <multiplier>-1.0</multiplier>
            <offset>0.0</offset>
            <hasPID />
        </plugin>
        <plugin filename="libroboticsgroup_gazebo_mimic_joint_plugin.so" name="mimic_moveo_3">
            <joint>Gripper_Servo_Gear_Joint</joint>
            <mimicJoint>Pivot_Arm_Gripper_Servo_Joint</mimicJoint>
            <multiplier>1.0</multiplier>
            <offset>0.0</offset>
            <hasPID />
        </plugin>
        <plugin filename="libroboticsgroup_gazebo_mimic_joint_plugin.so" name="mimic_moveo_4">
            <joint>Gripper_Idol_Gear_Joint</joint>
            <mimicJoint>Pivot_Arm_Gripper_Idol_Joint</mimicJoint>
            <multiplier>1.0</multiplier>
            <offset>0.0</offset>
            <hasPID />
        </plugin>
    </gazebo>
    <link name="base_footprint" />
    <joint name="base_joint" type="fixed">
        <parent link="base_footprint" />
        <child link="base_link" />
        <origin rpy="0 0 0" xyz="0 0 0.010" />
    </joint>
    <link name="base_link">
        <visual>
            <origin rpy="0 0 0" xyz="-0.064 0 0.0" />
            <geometry>
                <mesh filename="package://turtlebot3_description/meshes/bases/waffle_pi_base.stl" scale="0.001 0.001 0.001" />
            </geometry>
            <!-- <material name="light_black"/> -->
            <material name="turquoise" />
        </visual>
        <collision>
            <origin rpy="0 0 0" xyz="-0.064 0 0.047" />
            <geometry>
                <box size="0.266 0.266 0.094" />
            </geometry>
        </collision>
        <inertial>
            <origin rpy="0 0 0" xyz="0 0 0" />
            <mass value="1.3729096e+00" />
            <inertia ixx="8.7002718e-03" ixy="-4.7576583e-05" ixz="1.1160499e-04" iyy="8.6195418e-03" iyz="-3.5422299e-06" izz="1.4612727e-02" />
        </inertial>
    </link>
    <joint name="wheel_left_joint" type="continuous">
        <parent link="base_link" />
        <child link="wheel_left_link" />
        <origin rpy="-1.57 0 0" xyz="0.0 0.144 0.023" />
        <axis xyz="0 0 1" />
    </joint>
    <link name="wheel_left_link">
        <visual>
            <origin rpy="1.57 0 0" xyz="0 0 0" />
            <geometry>
                <mesh filename="package://turtlebot3_description/meshes/wheels/left_tire.stl" scale="0.001 0.001 0.001" />
            </geometry>
            <material name="yellow" />
        </visual>
        <collision>
            <origin rpy="0 0 0" xyz="0 0 0" />
            <geometry>
                <cylinder length="0.018" radius="0.033" />
            </geometry>
        </collision>
        <inertial>
            <origin xyz="0 0 0" rpy="0 0 0" />
            <mass value="2.8498940e-02" />
            <inertia ixx="1.1175580e-05" ixy="-4.2369783e-11" ixz="-5.9381719e-09" iyy="1.1192413e-05" iyz="-1.4400107e-11" izz="2.0712558e-05" />
        </inertial>
    </link>
    <joint name="wheel_right_joint" type="continuous">
        <parent link="base_link" />
        <child link="wheel_right_link" />
        <origin rpy="-1.57 0 0" xyz="0.0 -0.144 0.023" />
        <axis xyz="0 0 1" />
    </joint>
    <link name="wheel_right_link">
        <visual>
            <origin rpy="1.57 0 0" xyz="0 0 0" />
            <geometry>
                <mesh filename="package://turtlebot3_description/meshes/wheels/right_tire.stl" scale="0.001 0.001 0.001" />
            </geometry>
            <material name="yellow" />
        </visual>
        <collision>
            <origin rpy="0 0 0" xyz="0 0 0" />
            <geometry>
                <cylinder length="0.018" radius="0.033" />
            </geometry>
        </collision>
        <inertial>
            <origin xyz="0 0 0" rpy="0 0 0" />
            <mass value="2.8498940e-02" />
            <inertia ixx="1.1175580e-05" ixy="-4.2369783e-11" ixz="-5.9381719e-09" iyy="1.1192413e-05" iyz="-1.4400107e-11" izz="2.0712558e-05" />
        </inertial>
    </link>
    <joint name="caster_back_right_joint" type="fixed">
        <parent link="base_link" />
        <child link="caster_back_right_link" />
        <origin rpy="-1.57 0 0" xyz="-0.177 -0.064 -0.004" />
    </joint>
    <link name="caster_back_right_link">
        <collision>
            <origin rpy="0 0 0" xyz="0 0.001 0" />
            <geometry>
                <box size="0.030 0.009 0.020" />
            </geometry>
        </collision>
        <inertial>
            <origin xyz="0 0 0" rpy="0 0 0" />
            <mass value="0.005" />
            <inertia ixx="0.001" ixy="0.0" ixz="0.0" iyy="0.001" iyz="0.0" izz="0.001" />
        </inertial>
    </link>
    <joint name="caster_back_left_joint" type="fixed">
        <parent link="base_link" />
        <child link="caster_back_left_link" />
        <origin rpy="-1.57 0 0" xyz="-0.177 0.064 -0.004" />
    </joint>
    <link name="caster_back_left_link">
        <collision>
            <origin rpy="0 0 0" xyz="0 0.001 0" />
            <geometry>
                <box size="0.030 0.009 0.020" />
            </geometry>
        </collision>
        <inertial>
            <origin xyz="0 0 0" rpy="0 0 0" />
            <mass value="0.005" />
            <inertia ixx="0.001" ixy="0.0" ixz="0.0" iyy="0.001" iyz="0.0" izz="0.001" />
        </inertial>
    </link>
    <joint name="imu_joint" type="fixed">
        <parent link="base_link" />
        <child link="imu_link" />
        <origin rpy="0 0 0" xyz="0.0 0 0.068" />
    </joint>
    <link name="imu_link" />
    <joint name="scan_joint" type="fixed">
        <parent link="base_link" />
        <child link="base_scan" />
        <origin rpy="0 0 0" xyz="-0.064 0 0.122" />
    </joint>
    <link name="base_scan">
        <visual>
            <origin rpy="0 0 0" xyz="0 0 0.0" />
            <geometry>
                <mesh filename="package://turtlebot3_description/meshes/sensors/lds.stl" scale="0.001 0.001 0.001" />
            </geometry>
            <material name="dark" />
        </visual>
        <collision>
            <origin rpy="0 0 0" xyz="0.015 0 -0.0065" />
            <geometry>
                <cylinder length="0.0315" radius="0.055" />
            </geometry>
        </collision>
        <inertial>
            <mass value="0.114" />
            <origin xyz="0 0 0" rpy="0 0 0" />
            <inertia ixx="0.001" ixy="0.0" ixz="0.0" iyy="0.001" iyz="0.0" izz="0.001" />
        </inertial>
    </link>
    <joint name="camera_joint" type="fixed">
        <!-- <origin xyz="0.073 -0.011 0.084" rpy="0 0 0"/> -->
        <origin rpy="0 0 0" xyz="0.073 -0.011 1" />
        <parent link="base_link" />
        <child link="camera_link" />
    </joint>
    <link name="camera_link">
        <collision>
            <origin rpy="0 0 0" xyz="0.005 0.011 0.013" />
            <geometry>
                <box size="0.015 0.030 0.027" />
            </geometry>
        </collision>
        <inertial>
            <mass value="0.1" />
            <origin xyz="0 0 0" rpy="0 0 0" />
            <inertia ixx="0.03" iyy="0.03" izz="0.03" ixy="0.0" ixz="0.0" iyz="0.0" />
        </inertial>
    </link>
    <joint name="camera_rgb_joint" type="fixed">
        <origin rpy="0 0 0" xyz="0.003 0.011 0.009" />
        <parent link="camera_link" />
        <child link="camera_rgb_frame" />
    </joint>
    <link name="camera_rgb_frame" />
    <joint name="camera_rgb_optical_joint" type="fixed">
        <origin rpy="-1.57 0 -1.57" xyz="0 0 0" />
        <parent link="camera_rgb_frame" />
        <child link="camera_rgb_optical_frame" />
    </joint>
    <link name="camera_rgb_optical_frame" />
    <!-- ...................................................MANIPULATOR ................................ -->
    <joint name="Joint_1" type="revolute">
        <origin rpy="0 0 0" xyz="0 0 .13" />
        <axis xyz="0 0 1" />
        <limit effort="100" lower="-1.5707963268" upper="1.5707963268" velocity="1.919862177191" />
        <parent link="base_scan" />
        <child link="Link_1" />
    </joint>
    <link name="Link_1">
        <visual>
            <origin rpy="0 0 0" xyz="0 0 0" />
            <geometry>
                <mesh filename="package://moveo_urdf/meshes/Link_1_edited.STL" />
            </geometry>
            <material name="">
                <color rgba="0.75294 0.75294 0.75294 1" />
            </material>
        </visual>
        <collision>
            <origin rpy="0 0 0" xyz="0 0 0" />
            <geometry>
                <mesh filename="package://moveo_urdf/meshes/Link_1_edited.STL" />
            </geometry>
        </collision>
        <inertial>
            <mass value="0.1" />
            <inertia ixx="0.03" ixy="0.0" ixz="0.0" iyy="0.03" iyz="0.0" izz="0.03" />
            <origin xyz="0 0 0" rpy="0 0 0" />
        </inertial>
    </link>
    <link name="Link_2">
        <visual>
            <origin rpy="0 0 0" xyz="0 0 0" />
            <geometry>
                <mesh filename="package://moveo_urdf/meshes/Link_2_edited.STL" />
            </geometry>
            <material name="">
                <color rgba="0.75294 0.75294 0.75294 1" />
            </material>
        </visual>
        <collision>
            <origin rpy="0 0 0" xyz="0 0 0" />
            <geometry>
                <mesh filename="package://moveo_urdf/meshes/Link_2_edited.STL" />
            </geometry>
        </collision>
        <inertial>
            <mass value="0.1" />
            <inertia ixx="0.03" ixy="0.0" ixz="0.0" iyy="0.03" iyz="0.0" izz="0.03" />
            <origin xyz="0 0 0" rpy="0 0 0" />
        </inertial>
    </link>
    <joint name="Joint_2" type="revolute">
        <origin rpy="0 0 0" xyz="0 0 0.18264" />
        <parent link="Link_1" />
        <child link="Link_2" />
        <axis xyz="1 0 0" />
        <limit effort="100" lower="-1.5707963268" upper="1.5707963268" velocity="1.919862177191" />
    </joint>
    <link name="Link_3">
        <visual>
            <origin rpy="0 0 0" xyz="0 0 0" />
            <geometry>
                <mesh filename="package://moveo_urdf/meshes/Link_3_edited.STL" />
            </geometry>
            <material name="">
                <color rgba="0.75294 0.75294 0.75294 1" />
            </material>
        </visual>
        <collision>
            <origin rpy="0 0 0" xyz="0 0 0" />
            <geometry>
                <mesh filename="package://moveo_urdf/meshes/Link_3_edited.STL" />
            </geometry>
        </collision>
        <inertial>
            <mass value="0.1" />
            <inertia ixx="0.03" ixy="0.0" ixz="0.0" iyy="0.03" iyz="0.0" izz="0.03" />
            <origin xyz="0 0 0" rpy="0 0 0" />
        </inertial>
    </link>
    <joint name="Joint_3" type="revolute">
        <origin rpy="0 0 0" xyz="0 0 0.22" />
        <parent link="Link_2" />
        <child link="Link_3" />
        <axis xyz="1 0 0" />
        <limit effort="100" lower="-1.5707963268" upper="1.5707963268" velocity="1.919862177191" />
    </joint>
    <link name="Link_4">
        <visual>
            <origin rpy="0 0 0" xyz="0 0 0" />
            <geometry>
                <mesh filename="package://moveo_urdf/meshes/Link_4_edited.STL" />
            </geometry>
            <material name="">
                <color rgba="0.75294 0.75294 0.75294 1" />
            </material>
        </visual>
        <collision>
            <origin rpy="0 0 0" xyz="0 0 0" />
            <geometry>
                <mesh filename="package://moveo_urdf/meshes/Link_4_edited.STL" />
            </geometry>
        </collision>
        <inertial>
            <mass value="0.1" />
            <inertia ixx="0.03" ixy="0.0" ixz="0.0" iyy="0.03" iyz="0.0" izz="0.03" />
            <origin xyz="0 0 0" rpy="0 0 0" />
        </inertial>
    </link>
    <joint name="Joint_4" type="revolute">
        <origin rpy="0 0 0.0872664626" xyz="0.001 -0.002 0.16988" />
        <parent link="Link_3" />
        <child link="Link_4" />
        <axis xyz="0 0 1" />
        <limit effort="100" lower="-1.5707963268" upper="1.5707963268" velocity="1.919862177191" />
    </joint>
    <link name="Link_5">
        <visual>
            <origin rpy="0 0 0" xyz="0 0 0" />
            <geometry>
                <mesh filename="package://moveo_urdf/meshes/Link_5_edited.STL" />
            </geometry>
            <material name="">
                <color rgba="0.75294 0.75294 0.75294 1" />
            </material>
        </visual>
        <collision>
            <origin rpy="0 0 0" xyz="0 0 0" />
            <geometry>
                <mesh filename="package://moveo_urdf/meshes/Link_5_edited.STL" />
            </geometry>
        </collision>
        <inertial>
            <mass value="0.1" />
            <inertia ixx="0.03" ixy="0.0" ixz="0.0" iyy="0.03" iyz="0.0" izz="0.03" />
            <origin xyz="0 0 0" rpy="0 0 0" />
        </inertial>
    </link>
    <joint name="Joint_5" type="revolute">
        <origin rpy="0 0 -0.0872664626" xyz="-0.002 0.001 0.055" />
        <parent link="Link_4" />
        <child link="Link_5" />
        <axis xyz="1 0 0" />
        <limit effort="100" lower="-1.5707963268" upper="1.5707963268" velocity="1.919862177191" />
    </joint>
    <link name="Gripper_Servo_Gear">
        <visual>
            <origin rpy="0 0 0" xyz="0 0 0" />
            <geometry>
                <mesh filename="package://moveo_urdf/meshes/Gripper_Servo_Gear.STL" />
            </geometry>
            <material name="">
                <color rgba="0.9098 0.44314 0.031373 1" />
            </material>
        </visual>
        <collision>
            <origin rpy="0 0 0" xyz="0 0 0" />
            <geometry>
                <mesh filename="package://moveo_urdf/meshes/Gripper_Servo_Gear_col.STL" />
            </geometry>
        </collision>
        <inertial>
            <mass value="0.1" />
            <inertia ixx="0.03" ixy="0.0" ixz="0.0" iyy="0.03" iyz="0.0" izz="0.03" />
            <origin xyz="0 0 0" rpy="0 0 0" />
        </inertial>
    </link>
    <joint name="Gripper_Servo_Gear_Joint" type="revolute">
        <origin rpy="0 0.032705 0" xyz="-0.012 0 0.065" />
        <parent link="Link_5" />
        <child link="Gripper_Servo_Gear" />
        <axis xyz="0 1 0" />
        <limit effort="100" lower="0" upper="1.5707963268" velocity="0.5" />
    </joint>
    <link name="Gripper_Idol_Gear">
        <visual>
            <origin rpy="0 0 0" xyz="0 0 0" />
            <geometry>
                <mesh filename="package://moveo_urdf/meshes/Gripper_Idol_Gear.STL" />
            </geometry>
            <material name="">
                <color rgba="0.058824 0.64706 1 1" />
            </material>
        </visual>
        <collision>
            <origin rpy="0 0 0" xyz="0 0 0" />
            <geometry>
                <mesh filename="package://moveo_urdf/meshes/Gripper_Idol_Gear_col.STL" />
            </geometry>
        </collision>
        <inertial>
            <mass value="0.1" />
            <inertia ixx="0.03" ixy="0.0" ixz="0.0" iyy="0.03" iyz="0.0" izz="0.03" />
            <origin xyz="0 0 0" rpy="0 0 0" />
        </inertial>
    </link>
    <joint name="Gripper_Idol_Gear_Joint" type="revolute">
        <origin rpy="3.1415926536 -0.040996 3.1415926536" xyz="0.012 0 0.065" />
        <parent link="Link_5" />
        <child link="Gripper_Idol_Gear" />
        <axis xyz="0 1 0" />
        <limit effort="100" lower="-1.5707963268" upper="0" velocity="0.5" />
    </joint>
    <link name="Tip_Gripper_Idol">
        <visual>
            <origin rpy="0 0 0" xyz="0 0 0" />
            <geometry>
                <mesh filename="package://moveo_urdf/meshes/Tip_Gripper_Idol.STL" />
            </geometry>
            <material name="">
                <color rgba="0.79216 0.81961 0.93333 1" />
            </material>
        </visual>
        <collision>
            <origin rpy="0 0 0" xyz="0 0 0" />
            <geometry>
                <mesh filename="package://moveo_urdf/meshes/Tip_Gripper_Idol_col.STL" />
            </geometry>
        </collision>
        <inertial>
            <mass value="0.1" />
            <inertia ixx="0.03" ixy="0.0" ixz="0.0" iyy="0.03" iyz="0.0" izz="0.03" />
            <origin xyz="0 0 0" rpy="0 0 0" />
        </inertial>
    </link>
    <link name="Tip_Gripper_Servo">
        <visual>
            <origin rpy="0 0 0" xyz="0 0 0" />
            <geometry>
                <mesh filename="package://moveo_urdf/meshes/Tip_Gripper_Servo.STL" />
            </geometry>
            <material name="">
                <color rgba="0.6 1 0.27843 1" />
            </material>
        </visual>
        <collision>
            <origin rpy="0 0 0" xyz="0 0 0" />
            <geometry>
                <mesh filename="package://moveo_urdf/meshes/Tip_Gripper_Servo_col.STL" />
            </geometry>
        </collision>
        <inertial>
            <mass value="0.1" />
            <inertia ixx="0.03" ixy="0.0" ixz="0.0" iyy="0.03" iyz="0.0" izz="0.03" />
            <origin xyz="0 0 0" rpy="0 0 0" />
        </inertial>
    </link>
    <joint name="Tip_Gripper_Servo_Joint" type="revolute">
        <origin rpy="-3.1416 -1.5569 -2.0392E-12" xyz="-0.039906 -0.004 -0.0027473" />
        <parent link="Gripper_Servo_Gear" />
        <child link="Tip_Gripper_Servo" />
        <axis xyz="0 1 0" />
        <limit effort="100" lower="0" upper="1.3" velocity="0.5" />
        <mimic joint="Gripper_Servo_Gear_Joint" multiplier="1" offset="0" />
    </joint>
    <joint name="Tip_Gripper_Idol_Joint" type="revolute">
        <origin rpy="3.1416 0.5236 3.1416" xyz="-0.039906 -0.000125 -0.0027473" />
        <parent link="Gripper_Idol_Gear" />
        <child link="Tip_Gripper_Idol" />
        <axis xyz="0 1 0" />
        <limit effort="100" lower="3.14" upper="-3.14" velocity="0.5" />
        <mimic joint="Gripper_Idol_Gear_Joint" multiplier="-1" offset="0" />
    </joint>
    <link name="Pivot_Arm_Gripper_Servo">
        <visual>
            <origin rpy="0 0 0" xyz="0 0 0" />
            <geometry>
                <mesh filename="package://moveo_urdf/meshes/Pivot_Arm_Gripper_Servo.STL" />
            </geometry>
            <material name="">
                <color rgba="0.79216 0.81961 0.93333 1" />
            </material>
        </visual>
        <collision>
            <origin rpy="0 0 0" xyz="0 0 0" />
            <geometry>
                <mesh filename="package://moveo_urdf/meshes/Pivot_Arm_Gripper_Servo_col.STL" />
            </geometry>
        </collision>
        <inertial>
            <mass value="0.1" />
            <inertia ixx="0.03" ixy="0.0" ixz="0.0" iyy="0.03" iyz="0.0" izz="0.03" />
            <origin xyz="0 0 0" rpy="0 0 0" />
        </inertial>
    </link>
    <joint name="Pivot_Arm_Gripper_Servo_Joint" type="revolute">
        <origin rpy="0 -0.0083007 0" xyz="-0.005 0 0.085" />
        <parent link="Link_5" />
        <child link="Pivot_Arm_Gripper_Servo" />
        <axis xyz="0 1 0" />
        <limit effort="100" lower="-1.5707963268" upper="1.5707963268" velocity="0.5" />
        <mimic joint="Gripper_Servo_Gear_Joint" multiplier="1" offset="0" />
    </joint>
    <link name="Pivot_Arm_Gripper_Idol">
        <visual>
            <origin rpy="0 0 0" xyz="0 0 0" />
            <geometry>
                <mesh filename="package://moveo_urdf/meshes/Pivot_Arm_Gripper_Idol.STL" />
            </geometry>
            <material name="">
                <color rgba="0.79216 0.81961 0.93333 1" />
            </material>
        </visual>
        <collision>
            <origin rpy="0 0 0" xyz="0 0 0" />
            <geometry>
                <mesh filename="package://moveo_urdf/meshes/Pivot_Arm_Gripper_Idol_col.STL" />
            </geometry>
        </collision>
        <inertial>
            <mass value="0.1" />
            <inertia ixx="0.03" ixy="0.0" ixz="0.0" iyy="0.03" iyz="0.0" izz="0.03" />
            <origin xyz="0 0 0" rpy="0 0 0" />
        </inertial>
    </link>
    <joint name="Pivot_Arm_Gripper_Idol_Joint" type="revolute">
        <origin rpy="0 0 0" xyz="0.005 0 0.085" />
        <parent link="Link_5" />
        <child link="Pivot_Arm_Gripper_Idol" />
        <axis xyz="0 1 0" />
        <limit effort="100" lower="-1.5707963268" upper="1.5707963268" velocity="0.5" />
        <mimic joint="Gripper_Idol_Gear_Joint" multiplier="1" offset="0" />
    </joint>
    <transmission name="trans_wheel_left_joint">
        <type>transmission_interface/SimpleTransmission</type>
        <joint name="wheel_left_joint">
            <hardwareInterface>hardware_interface/EffortJointInterface</hardwareInterface>
        </joint>
        <actuator name="wheel_left_joint_motor">
            <hardwareInterface>hardware_interface/EffortJointInterface</hardwareInterface>
            <mechanicalReduction>1</mechanicalReduction>
        </actuator>
    </transmission>
    <transmission name="trans_wheel_right_joint">
        <type>transmission_interface/SimpleTransmission</type>
        <joint name="wheel_right_joint">
            <hardwareInterface>hardware_interface/EffortJointInterface</hardwareInterface>
        </joint>
        <actuator name="wheel_right_joint_motor">
            <hardwareInterface>hardware_interface/EffortJointInterface</hardwareInterface>
            <mechanicalReduction>1</mechanicalReduction>
        </actuator>
    </transmission>
    <transmission name="trans_Tip_Gripper_Servo_Joint">
        <type>transmission_interface/SimpleTransmission</type>
        <joint name="Tip_Gripper_Servo_Joint">
            <hardwareInterface>hardware_interface/EffortJointInterface</hardwareInterface>
        </joint>
        <actuator name="Tip_Gripper_Servo_Joint_motor">
            <hardwareInterface>hardware_interface/EffortJointInterface</hardwareInterface>
            <mechanicalReduction>1</mechanicalReduction>
        </actuator>
    </transmission>
    <transmission name="trans_Tip_Gripper_Idol_Joint">
        <type>transmission_interface/SimpleTransmission</type>
        <joint name="Tip_Gripper_Idol_Joint">
            <hardwareInterface>hardware_interface/EffortJointInterface</hardwareInterface>
        </joint>
        <actuator name="Tip_Gripper_Idol_Joint_motor">
            <hardwareInterface>hardware_interface/EffortJointInterface</hardwareInterface>
            <mechanicalReduction>1</mechanicalReduction>
        </actuator>
    </transmission>
    <transmission name="trans_Pivot_Arm_Gripper_Servo_Joint">
        <type>transmission_interface/SimpleTransmission</type>
        <joint name="Pivot_Arm_Gripper_Servo_Joint">
            <hardwareInterface>hardware_interface/EffortJointInterface</hardwareInterface>
        </joint>
        <actuator name="Pivot_Arm_Gripper_Servo_Joint_motor">
            <hardwareInterface>hardware_interface/EffortJointInterface</hardwareInterface>
            <mechanicalReduction>1</mechanicalReduction>
        </actuator>
    </transmission>
    <transmission name="trans_Pivot_Arm_Gripper_Idol_Joint">
        <type>transmission_interface/SimpleTransmission</type>
        <joint name="Pivot_Arm_Gripper_Idol_Joint">
            <hardwareInterface>hardware_interface/EffortJointInterface</hardwareInterface>
        </joint>
        <actuator name="Pivot_Arm_Gripper_Idol_Joint_motor">
            <hardwareInterface>hardware_interface/EffortJointInterface</hardwareInterface>
            <mechanicalReduction>1</mechanicalReduction>
        </actuator>
    </transmission>
</robot>

