<?xml version="1.0" ?>
<!-- =================================================================================== -->
<!-- |    This document was autogenerated by xacro from /home/mast/catkin_ws/src/franka_ros/franka_description/robots/panda/panda.urdf.xacro | -->
<!-- |    EDITING THIS FILE BY HAND IS NOT RECOMMENDED                                 | -->
<!-- =================================================================================== -->
<robot name="panda">
    <!-- sub-link defining detailed meshes for collision with environment -->
    <link name="panda_link0">
        <visual>
            <geometry>
                <mesh filename="package://franka_description/meshes/visual/link0.dae" />
            </geometry>
        </visual>
        <collision>
            <geometry>
                <mesh filename="package://franka_description/meshes/collision/link0.stl" />
            </geometry>
        </collision>
        <inertial>
            <mass value="0.1" />
            <origin xyz="0 0 0" rpy="0 0 0" />
            <inertia ixx="0.03" iyy="0.03" izz="0.03" ixy="0.0" ixz="0.0" iyz="0.0" />
        </inertial>
    </link>
    <!-- sub-link defining coarse geometries of real robot's internal self-collision -->
    <link name="panda_link0_sc">
        <collision>
            <origin rpy="0 1.5707963267948966 0" xyz="-0.075 0 0.06" />
            <geometry>
                <cylinder length="0.03" radius="0.09" />
            </geometry>
        </collision>
        <collision>
            <origin xyz="-0.06 0 0.06" />
            <geometry>
                <sphere radius="0.09" />
            </geometry>
        </collision>
        <collision>
            <origin xyz="-0.09 0 0.06" />
            <geometry>
                <sphere radius="0.09" />
            </geometry>
        </collision>
        <inertial>
            <mass value="0.1" />
            <origin xyz="0 0 0" rpy="0 0 0" />
            <inertia ixx="0.03" iyy="0.03" izz="0.03" ixy="0.0" ixz="0.0" iyz="0.0" />
        </inertial>
    </link>
    <!-- fixed joint between both sub-links -->
    <joint name="panda_link0_sc_joint" type="fixed">
        <origin rpy="0 0 0" />
        <parent link="panda_link0" />
        <child link="panda_link0_sc" />
    </joint>
    <!-- sub-link defining detailed meshes for collision with environment -->
    <link name="panda_link1">
        <visual>
            <geometry>
                <mesh filename="package://franka_description/meshes/visual/link1.dae" />
            </geometry>
        </visual>
        <collision>
            <geometry>
                <mesh filename="package://franka_description/meshes/collision/link1.stl" />
            </geometry>
        </collision>
        <inertial>
            <mass value="0.1" />
            <origin xyz="0 0 0" rpy="0 0 0" />
            <inertia ixx="0.03" iyy="0.03" izz="0.03" ixy="0.0" ixz="0.0" iyz="0.0" />
        </inertial>
    </link>
    <!-- sub-link defining coarse geometries of real robot's internal self-collision -->
    <link name="panda_link1_sc">
        <collision>
            <origin rpy="0 0 0" xyz="0 0 -0.1915" />
            <geometry>
                <cylinder length="0.283" radius="0.09" />
            </geometry>
        </collision>
        <collision>
            <origin xyz="0 0 -0.05000000000000002" />
            <geometry>
                <sphere radius="0.09" />
            </geometry>
        </collision>
        <collision>
            <origin xyz="0 0 -0.33299999999999996" />
            <geometry>
                <sphere radius="0.09" />
            </geometry>
        </collision>
        <inertial>
            <mass value="0.1" />
            <origin xyz="0 0 0" rpy="0 0 0" />
            <inertia ixx="0.03" iyy="0.03" izz="0.03" ixy="0.0" ixz="0.0" iyz="0.0" />
        </inertial>
    </link>
    <!-- fixed joint between both sub-links -->
    <joint name="panda_link1_sc_joint" type="fixed">
        <origin rpy="0 0 0" />
        <parent link="panda_link1" />
        <child link="panda_link1_sc" />
    </joint>
    <joint name="panda_joint1" type="revolute">
        <origin rpy="0 0 0" xyz="0 0 0.333" />
        <parent link="panda_link0" />
        <child link="panda_link1" />
        <axis xyz="0 0 1" />
        <limit effort="87.0" lower="-2.8973" upper="2.8973" velocity="2.175" />
        <safety_controller k_position="100.0" k_velocity="40.0" soft_lower_limit="-2.8973" soft_upper_limit="2.8973" />
        <dynamics D="1" K="7000" damping="0.003" friction="0.0" mu_coulomb="0" mu_viscous="16" />
    </joint>
    <!-- sub-link defining detailed meshes for collision with environment -->
    <link name="panda_link2">
        <visual>
            <geometry>
                <mesh filename="package://franka_description/meshes/visual/link2.dae" />
            </geometry>
        </visual>
        <collision>
            <geometry>
                <mesh filename="package://franka_description/meshes/collision/link2.stl" />
            </geometry>
        </collision>
        <inertial>
            <mass value="0.1" />
            <origin xyz="0 0 0" rpy="0 0 0" />
            <inertia ixx="0.03" iyy="0.03" izz="0.03" ixy="0.0" ixz="0.0" iyz="0.0" />
        </inertial>
    </link>
    <!-- sub-link defining coarse geometries of real robot's internal self-collision -->
    <link name="panda_link2_sc">
        <collision>
            <origin rpy="0 0 0" xyz="0 0 0" />
            <geometry>
                <cylinder length="0.12" radius="0.09" />
            </geometry>
        </collision>
        <collision>
            <origin xyz="0 0 0.06" />
            <geometry>
                <sphere radius="0.09" />
            </geometry>
        </collision>
        <collision>
            <origin xyz="0 0 -0.06" />
            <geometry>
                <sphere radius="0.09" />
            </geometry>
        </collision>
        <inertial>
            <mass value="0.1" />
            <origin xyz="0 0 0" rpy="0 0 0" />
            <inertia ixx="0.03" iyy="0.03" izz="0.03" ixy="0.0" ixz="0.0" iyz="0.0" />
        </inertial>
    </link>
    <!-- fixed joint between both sub-links -->
    <joint name="panda_link2_sc_joint" type="fixed">
        <origin rpy="0 0 0" />
        <parent link="panda_link2" />
        <child link="panda_link2_sc" />
    </joint>
    <joint name="panda_joint2" type="revolute">
        <origin rpy="-1.5707963267948966 0 0" xyz="0 0 0" />
        <parent link="panda_link1" />
        <child link="panda_link2" />
        <axis xyz="0 0 1" />
        <limit effort="87.0" lower="-1.7628" upper="1.7628" velocity="2.175" />
        <safety_controller k_position="100.0" k_velocity="40.0" soft_lower_limit="-1.7628" soft_upper_limit="1.7628" />
        <dynamics D="1" K="7000" damping="0.003" friction="0.0" mu_coulomb="0" mu_viscous="16" />
    </joint>
    <!-- sub-link defining detailed meshes for collision with environment -->
    <link name="panda_link3">
        <visual>
            <geometry>
                <mesh filename="package://franka_description/meshes/visual/link3.dae" />
            </geometry>
        </visual>
        <collision>
            <geometry>
                <mesh filename="package://franka_description/meshes/collision/link3.stl" />
            </geometry>
        </collision>
        <inertial>
            <mass value="0.1" />
            <origin xyz="0 0 0" rpy="0 0 0" />
            <inertia ixx="0.03" iyy="0.03" izz="0.03" ixy="0.0" ixz="0.0" iyz="0.0" />
        </inertial>
    </link>
    <!-- sub-link defining coarse geometries of real robot's internal self-collision -->
    <link name="panda_link3_sc">
        <collision>
            <origin rpy="0 0 0" xyz="0 0 -0.145" />
            <geometry>
                <cylinder length="0.15" radius="0.09" />
            </geometry>
        </collision>
        <collision>
            <origin xyz="0 0 -0.06999999999999999" />
            <geometry>
                <sphere radius="0.09" />
            </geometry>
        </collision>
        <collision>
            <origin xyz="0 0 -0.21999999999999997" />
            <geometry>
                <sphere radius="0.09" />
            </geometry>
        </collision>
        <inertial>
            <mass value="0.1" />
            <origin xyz="0 0 0" rpy="0 0 0" />
            <inertia ixx="0.03" iyy="0.03" izz="0.03" ixy="0.0" ixz="0.0" iyz="0.0" />
        </inertial>
    </link>
    <!-- fixed joint between both sub-links -->
    <joint name="panda_link3_sc_joint" type="fixed">
        <origin rpy="0 0 0" />
        <parent link="panda_link3" />
        <child link="panda_link3_sc" />
    </joint>
    <joint name="panda_joint3" type="revolute">
        <origin rpy="1.5707963267948966 0 0" xyz="0 -0.316 0" />
        <parent link="panda_link2" />
        <child link="panda_link3" />
        <axis xyz="0 0 1" />
        <limit effort="87.0" lower="-2.8973" upper="2.8973" velocity="2.175" />
        <safety_controller k_position="100.0" k_velocity="40.0" soft_lower_limit="-2.8973" soft_upper_limit="2.8973" />
        <dynamics D="1" K="7000" damping="0.003" friction="0.0" mu_coulomb="0" mu_viscous="16" />
    </joint>
    <!-- sub-link defining detailed meshes for collision with environment -->
    <link name="panda_link4">
        <visual>
            <geometry>
                <mesh filename="package://franka_description/meshes/visual/link4.dae" />
            </geometry>
        </visual>
        <collision>
            <geometry>
                <mesh filename="package://franka_description/meshes/collision/link4.stl" />
            </geometry>
        </collision>
        <inertial>
            <mass value="0.1" />
            <origin xyz="0 0 0" rpy="0 0 0" />
            <inertia ixx="0.03" iyy="0.03" izz="0.03" ixy="0.0" ixz="0.0" iyz="0.0" />
        </inertial>
    </link>
    <!-- sub-link defining coarse geometries of real robot's internal self-collision -->
    <link name="panda_link4_sc">
        <collision>
            <origin rpy="0 0 0" xyz="0 0 0" />
            <geometry>
                <cylinder length="0.12" radius="0.09" />
            </geometry>
        </collision>
        <collision>
            <origin xyz="0 0 0.06" />
            <geometry>
                <sphere radius="0.09" />
            </geometry>
        </collision>
        <collision>
            <origin xyz="0 0 -0.06" />
            <geometry>
                <sphere radius="0.09" />
            </geometry>
        </collision>
        <inertial>
            <mass value="0.1" />
            <origin xyz="0 0 0" rpy="0 0 0" />
            <inertia ixx="0.03" iyy="0.03" izz="0.03" ixy="0.0" ixz="0.0" iyz="0.0" />
        </inertial>
    </link>
    <!-- fixed joint between both sub-links -->
    <joint name="panda_link4_sc_joint" type="fixed">
        <origin rpy="0 0 0" />
        <parent link="panda_link4" />
        <child link="panda_link4_sc" />
    </joint>
    <joint name="panda_joint4" type="revolute">
        <origin rpy="1.5707963267948966 0 0" xyz="0.0825 0 0" />
        <parent link="panda_link3" />
        <child link="panda_link4" />
        <axis xyz="0 0 1" />
        <limit effort="87.0" lower="-3.0718" upper="-0.0698" velocity="2.175" />
        <safety_controller k_position="100.0" k_velocity="40.0" soft_lower_limit="-3.0718" soft_upper_limit="-0.0698" />
        <dynamics D="1" K="7000" damping="0.003" friction="0.0" mu_coulomb="0" mu_viscous="16" />
    </joint>
    <!-- sub-link defining detailed meshes for collision with environment -->
    <link name="panda_link5">
        <visual>
            <geometry>
                <mesh filename="package://franka_description/meshes/visual/link5.dae" />
            </geometry>
        </visual>
        <collision>
            <geometry>
                <mesh filename="package://franka_description/meshes/collision/link5.stl" />
            </geometry>
        </collision>
        <inertial>
            <mass value="0.1" />
            <origin xyz="0 0 0" rpy="0 0 0" />
            <inertia ixx="0.03" iyy="0.03" izz="0.03" ixy="0.0" ixz="0.0" iyz="0.0" />
        </inertial>
    </link>
    <!-- sub-link defining coarse geometries of real robot's internal self-collision -->
    <link name="panda_link5_sc">
        <collision>
            <origin rpy="0 0 0" xyz="0 0 -0.26" />
            <geometry>
                <cylinder length="0.1" radius="0.09" />
            </geometry>
        </collision>
        <collision>
            <origin xyz="0 0 -0.21000000000000002" />
            <geometry>
                <sphere radius="0.09" />
            </geometry>
        </collision>
        <collision>
            <origin xyz="0 0 -0.31" />
            <geometry>
                <sphere radius="0.09" />
            </geometry>
        </collision>
        <collision>
            <origin rpy="0 0 0.08" xyz="0 0.08 -0.13" />
            <geometry>
                <cylinder length="0.14" radius="0.055" />
            </geometry>
        </collision>
        <collision>
            <origin xyz="0 0.08 -0.06" />
            <geometry>
                <sphere radius="0.055" />
            </geometry>
        </collision>
        <collision>
            <origin xyz="0 0.08 -0.2" />
            <geometry>
                <sphere radius="0.055" />
            </geometry>
        </collision>
        <inertial>
            <mass value="0.1" />
            <origin xyz="0 0 0" rpy="0 0 0" />
            <inertia ixx="0.03" iyy="0.03" izz="0.03" ixy="0.0" ixz="0.0" iyz="0.0" />
        </inertial>
    </link>
    <!-- fixed joint between both sub-links -->
    <joint name="panda_link5_sc_joint" type="fixed">
        <origin rpy="0 0 0" />
        <parent link="panda_link5" />
        <child link="panda_link5_sc" />
    </joint>
    <joint name="panda_joint5" type="revolute">
        <origin rpy="-1.5707963267948966 0 0" xyz="-0.0825 0.384 0" />
        <parent link="panda_link4" />
        <child link="panda_link5" />
        <axis xyz="0 0 1" />
        <limit effort="12.0" lower="-2.8973" upper="2.8973" velocity="2.61" />
        <safety_controller k_position="100.0" k_velocity="40.0" soft_lower_limit="-2.8973" soft_upper_limit="2.8973" />
        <dynamics D="1" K="7000" damping="0.003" friction="0.0" mu_coulomb="0" mu_viscous="16" />
    </joint>
    <!-- sub-link defining detailed meshes for collision with environment -->
    <link name="panda_link6">
        <visual>
            <geometry>
                <mesh filename="package://franka_description/meshes/visual/link6.dae" />
            </geometry>
        </visual>
        <collision>
            <geometry>
                <mesh filename="package://franka_description/meshes/collision/link6.stl" />
            </geometry>
        </collision>
        <inertial>
            <mass value="0.1" />
            <origin xyz="0 0 0" rpy="0 0 0" />
            <inertia ixx="0.03" iyy="0.03" izz="0.03" ixy="0.0" ixz="0.0" iyz="0.0" />
        </inertial>
    </link>
    <!-- sub-link defining coarse geometries of real robot's internal self-collision -->
    <link name="panda_link6_sc">
        <collision>
            <origin rpy="0 0 0" xyz="0 0 -0.03" />
            <geometry>
                <cylinder length="0.08" radius="0.08" />
            </geometry>
        </collision>
        <collision>
            <origin xyz="0 0 0.010000000000000002" />
            <geometry>
                <sphere radius="0.08" />
            </geometry>
        </collision>
        <collision>
            <origin xyz="0 0 -0.07" />
            <geometry>
                <sphere radius="0.08" />
            </geometry>
        </collision>
        <inertial>
            <mass value="0.1" />
            <origin xyz="0 0 0" rpy="0 0 0" />
            <inertia ixx="0.03" iyy="0.03" izz="0.03" ixy="0.0" ixz="0.0" iyz="0.0" />
        </inertial>
    </link>
    <!-- fixed joint between both sub-links -->
    <joint name="panda_link6_sc_joint" type="fixed">
        <origin rpy="0 0 0" />
        <parent link="panda_link6" />
        <child link="panda_link6_sc" />
    </joint>
    <joint name="panda_joint6" type="revolute">
        <origin rpy="1.5707963267948966 0 0" xyz="0 0 0" />
        <parent link="panda_link5" />
        <child link="panda_link6" />
        <axis xyz="0 0 1" />
        <limit effort="12.0" lower="-0.0175" upper="3.7525" velocity="2.61" />
        <safety_controller k_position="100.0" k_velocity="40.0" soft_lower_limit="-0.0175" soft_upper_limit="3.7525" />
        <dynamics D="1" K="7000" damping="0.003" friction="0.0" mu_coulomb="0" mu_viscous="16" />
    </joint>
    <!-- sub-link defining detailed meshes for collision with environment -->
    <link name="panda_link7">
        <visual>
            <geometry>
                <mesh filename="package://franka_description/meshes/visual/link7.dae" />
            </geometry>
        </visual>
        <collision>
            <geometry>
                <mesh filename="package://franka_description/meshes/collision/link7.stl" />
            </geometry>
        </collision>
        <inertial>
            <mass value="0.1" />
            <origin xyz="0 0 0" rpy="0 0 0" />
            <inertia ixx="0.03" iyy="0.03" izz="0.03" ixy="0.0" ixz="0.0" iyz="0.0" />
        </inertial>
    </link>
    <!-- sub-link defining coarse geometries of real robot's internal self-collision -->
    <link name="panda_link7_sc">
        <collision>
            <origin rpy="0 0 0" xyz="0 0 0.01" />
            <geometry>
                <cylinder length="0.14" radius="0.07" />
            </geometry>
        </collision>
        <collision>
            <origin xyz="0 0 0.08" />
            <geometry>
                <sphere radius="0.07" />
            </geometry>
        </collision>
        <collision>
            <origin xyz="0 0 -0.060000000000000005" />
            <geometry>
                <sphere radius="0.07" />
            </geometry>
        </collision>
        <collision>
            <origin rpy="0 1.5707963267948966 0" xyz="0.06 0 0.082" />
            <geometry>
                <cylinder length="0.01" radius="0.06" />
            </geometry>
        </collision>
        <collision>
            <origin xyz="0.065 0 0.082" />
            <geometry>
                <sphere radius="0.06" />
            </geometry>
        </collision>
        <collision>
            <origin xyz="0.055 0 0.082" />
            <geometry>
                <sphere radius="0.06" />
            </geometry>
        </collision>
        <inertial>
            <mass value="0.1" />
            <origin xyz="0 0 0" rpy="0 0 0" />
            <inertia ixx="0.03" iyy="0.03" izz="0.03" ixy="0.0" ixz="0.0" iyz="0.0" />
        </inertial>
    </link>
    <!-- fixed joint between both sub-links -->
    <joint name="panda_link7_sc_joint" type="fixed">
        <origin rpy="0 0 0.7853981633974483" />
        <parent link="panda_link7" />
        <child link="panda_link7_sc" />
    </joint>
    <joint name="panda_joint7" type="revolute">
        <origin rpy="1.5707963267948966 0 0" xyz="0.088 0 0" />
        <parent link="panda_link6" />
        <child link="panda_link7" />
        <axis xyz="0 0 1" />
        <limit effort="12.0" lower="-2.8973" upper="2.8973" velocity="2.61" />
        <safety_controller k_position="100.0" k_velocity="40.0" soft_lower_limit="-2.8973" soft_upper_limit="2.8973" />
        <dynamics D="1" K="7000" damping="0.003" friction="0.0" mu_coulomb="0" mu_viscous="16" />
    </joint>
    <link name="panda_link8" />
    <joint name="panda_joint8" type="fixed">
        <origin rpy="0 0 0" xyz="0 0 0.107" />
        <parent link="panda_link7" />
        <child link="panda_link8" />
    </joint>
    <joint name="arm_hand" type="fixed">
        <origin rpy="0 0 0" xyz="0 0 0" />
        <parent link="panda_link8" />
        <child link="wrist_plate" />
    </joint>
    ****************WRIST PLATE*************************
    <link name="wrist_plate">
        <visual>
            <geometry>
                <mesh filename="package://ar10_description/meshes/wrist plate.STL" scale=".001 .001 .001" />
            </geometry>
            <origin rpy="1.57 0 0" xyz=" -.03645 .0291 -.002 " />
            <material name="blue">
                <color rgba=".1 .1 .4 1" />
            </material>
        </visual>
        <collision>
            <geometry>
                <cylinder length=".002" radius=".06" />
            </geometry>
        </collision>
        <inertial>
            <mass value="1" />
            <inertia ixx="0.4" ixy="0.0" ixz="0.0" iyy="0.4" iyz="0.0" izz="0.2" />
            <origin xyz="0 0 0" rpy="0 0 0" />
        </inertial>
    </link>
    <link name="circuit_support">
        <visual>
            <geometry>
                <box size=".05 .05 .05" />
            </geometry>
            <origin xyz="0 0 .025" />
            <material name="black">
                <color rgba=".1 .1 .1 1" />
            </material>
        </visual>
        <collision>
            <geometry>
                <box size=".05 .05 .05" />
            </geometry>
            <origin xyz="0 0 .025" />
        </collision>
        <inertial>
            <mass value="1" />
            <inertia ixx="0.4" ixy="0.0" ixz="0.0" iyy="0.4" iyz="0.0" izz="0.2" />
            <origin xyz="0 0 0" rpy="0 0 0" />
        </inertial>
    </link>
    <joint name="wrist_plate_to_circuit_support" type="fixed">
        <parent link="wrist_plate" />
        <child link="circuit_support" />
        <origin xyz="0 0 0" />
    </joint>
    ****************PALM*************************
    <link name="palm">
        <visual>
            <geometry>
                <mesh filename="package://ar10_description/meshes/Palm -RIGHT.STL" scale=".001 .001 .001" />
            </geometry>
            <origin rpy="1.57 0 0" xyz="-.05675 .005 .002" />
            <material name="blue" />
        </visual>
        <collision>
            <geometry>
                <mesh filename="package://ar10_description/meshes/Palm -RIGHT.STL" scale=".001 .001 .001" />
            </geometry>
            <origin rpy="1.57 0 0" xyz="-.05675 .005 .002" />
        </collision>
        <inertial>
            <mass value="1" />
            <inertia ixx="0.4" ixy="0.0" ixz="0.0" iyy="0.4" iyz="0.0" izz="0.2" />
            <origin xyz="0 0 0" rpy="0 0 0" />
        </inertial>
    </link>
    <joint name="circuit_support_to_palm" type="fixed">
        <parent link="circuit_support" />
        <child link="palm" />
        <origin xyz="0 .0155 .04815" />
    </joint>
    *******************RBS********************************
    <link name="rb1">
        <visual>
            <geometry>
                <mesh filename="package://ar10_description/meshes/rod-end-2mm-BLUE.STL" scale=".001 .001 .001" />
            </geometry>
            <origin rpy="3.14 0 1.57" xyz="-.002 -.00375 .00375" />
            <material name="lightblue">
                <color rgba=".3 .5 .7 1" />
            </material>
        </visual>
        <collision>
            <geometry>
                <mesh filename="package://ar10_description/meshes/rod-end-2mm-BLUE.STL" scale=".001 .001 .001" />
            </geometry>
            <origin rpy="3.14 0 1.57" xyz="-.002 -.00375 .00375" />
        </collision>
        <inertial>
            <mass value="1" />
            <inertia ixx="0.4" ixy="0.0" ixz="0.0" iyy="0.4" iyz="0.0" izz="0.2" />
            <origin xyz="0 0 0" rpy="0 0 0" />
        </inertial>
    </link>
    <joint name="rb1_to_palm" type="fixed">
        <parent link="palm" />
        <child link="rb1" />
        <origin xyz=".0235 -.012 .08" />
    </joint>
    <link name="rb2">
        <visual>
            <geometry>
                <mesh filename="package://ar10_description/meshes/rod-end-2mm-BLUE.STL" scale=".001 .001 .001" />
            </geometry>
            <origin rpy="3.14 0 1.57" xyz="-.002 -.00375 .00375" />
            <material name="lightblue" />
        </visual>
        <collision>
            <geometry>
                <mesh filename="package://ar10_description/meshes/rod-end-2mm-BLUE.STL" scale=".001 .001 .001" />
            </geometry>
            <origin rpy="3.14 0 1.57" xyz="-.002 -.00375 .00375" />
        </collision>
        <inertial>
            <mass value="1" />
            <inertia ixx="0.4" ixy="0.0" ixz="0.0" iyy="0.4" iyz="0.0" izz="0.2" />
            <origin xyz="0 0 0" rpy="0 0 0" />
        </inertial>
    </link>
    <joint name="rb2_to_palm" type="fixed">
        <parent link="palm" />
        <child link="rb2" />
        <origin xyz=".0105 -.012 .08" />
    </joint>
    <link name="rb3">
        <visual>
            <geometry>
                <mesh filename="package://ar10_description/meshes/rod-end-2mm-BLUE.STL" scale=".001 .001 .001" />
            </geometry>
            <origin rpy="3.14 0 1.57" xyz="-.002 -.00375 .00375" />
            <material name="lightblue" />
        </visual>
        <collision>
            <geometry>
                <mesh filename="package://ar10_description/meshes/rod-end-2mm-BLUE.STL" scale=".001 .001 .001" />
            </geometry>
            <origin rpy="3.14 0 1.57" xyz="-.002 -.00375 .00375" />
        </collision>
        <inertial>
            <mass value="1" />
            <inertia ixx="0.4" ixy="0.0" ixz="0.0" iyy="0.4" iyz="0.0" izz="0.2" />
            <origin xyz="0 0 0" rpy="0 0 0" />
        </inertial>
    </link>
    <joint name="rb3_to_palm" type="fixed">
        <parent link="palm" />
        <child link="rb3" />
        <origin xyz=".0027 -.012 .09" />
    </joint>
    <link name="rb4">
        <visual>
            <geometry>
                <mesh filename="package://ar10_description/meshes/rod-end-2mm-BLUE.STL" scale=".001 .001 .001" />
            </geometry>
            <origin rpy="3.14 0 1.57" xyz="-.002 -.00375 .00375" />
            <material name="lightblue" />
        </visual>
        <collision>
            <geometry>
                <mesh filename="package://ar10_description/meshes/rod-end-2mm-BLUE.STL" scale=".001 .001 .001" />
            </geometry>
            <origin rpy="3.14 0 1.57" xyz="-.002 -.00375 .00375" />
        </collision>
        <inertial>
            <mass value="1" />
            <inertia ixx="0.4" ixy="0.0" ixz="0.0" iyy="0.4" iyz="0.0" izz="0.2" />
            <origin xyz="0 0 0" rpy="0 0 0" />
        </inertial>
    </link>
    <joint name="rb4_to_palm" type="fixed">
        <parent link="palm" />
        <child link="rb4" />
        <origin xyz="-.011 -.012 .09" />
    </joint>
    <link name="rb5">
        <visual>
            <geometry>
                <mesh filename="package://ar10_description/meshes/rod-end-2mm-BLUE.STL" scale=".001 .001 .001" />
            </geometry>
            <origin rpy="3.14 0 1.57" xyz="-.002 -.00375 .00375" />
            <material name="lightblue" />
        </visual>
        <collision>
            <geometry>
                <mesh filename="package://ar10_description/meshes/rod-end-2mm-BLUE.STL" scale=".001 .001 .001" />
            </geometry>
            <origin rpy="3.14 0 1.57" xyz="-.002 -.00375 .00375" />
        </collision>
        <inertial>
            <mass value="1" />
            <inertia ixx="0.4" ixy="0.0" ixz="0.0" iyy="0.4" iyz="0.0" izz="0.2" />
            <origin xyz="0 0 0" rpy="0 0 0" />
        </inertial>
    </link>
    <joint name="rb5_to_palm" type="fixed">
        <parent link="palm" />
        <child link="rb5" />
        <origin xyz="-.019 -.012 .1" />
    </joint>
    <link name="rb6">
        <visual>
            <geometry>
                <mesh filename="package://ar10_description/meshes/rod-end-2mm-BLUE.STL" scale=".001 .001 .001" />
            </geometry>
            <origin rpy="3.14 0 1.57" xyz="-.002 -.00375 .00375" />
            <material name="lightblue" />
        </visual>
        <collision>
            <geometry>
                <mesh filename="package://ar10_description/meshes/rod-end-2mm-BLUE.STL" scale=".001 .001 .001" />
            </geometry>
            <origin rpy="3.14 0 1.57" xyz="-.002 -.00375 .00375" />
        </collision>
        <inertial>
            <mass value="1" />
            <inertia ixx="0.4" ixy="0.0" ixz="0.0" iyy="0.4" iyz="0.0" izz="0.2" />
            <origin xyz="0 0 0" rpy="0 0 0" />
        </inertial>
    </link>
    <joint name="rb6_to_palm" type="fixed">
        <parent link="palm" />
        <child link="rb6" />
        <origin xyz="-.032 -.012 .1" />
    </joint>
    <link name="rb7">
        <visual>
            <geometry>
                <mesh filename="package://ar10_description/meshes/rod-end-2mm-BLUE.STL" scale=".001 .001 .001" />
            </geometry>
            <origin rpy="3.14 0 1.57" xyz="-.002 -.00375 .00375" />
            <material name="lightblue" />
        </visual>
        <collision>
            <geometry>
                <mesh filename="package://ar10_description/meshes/rod-end-2mm-BLUE.STL" scale=".001 .001 .001" />
            </geometry>
            <origin rpy="3.14 0 1.57" xyz="-.002 -.00375 .00375" />
        </collision>
        <inertial>
            <mass value="1" />
            <inertia ixx="0.4" ixy="0.0" ixz="0.0" iyy="0.4" iyz="0.0" izz="0.2" />
            <origin xyz="0 0 0" rpy="0 0 0" />
        </inertial>
    </link>
    <joint name="rb7_to_palm" type="fixed">
        <parent link="palm" />
        <child link="rb7" />
        <origin xyz="-.04 -.012 .095" />
    </joint>
    <link name="rb8">
        <visual>
            <geometry>
                <mesh filename="package://ar10_description/meshes/rod-end-2mm-BLUE.STL" scale=".001 .001 .001" />
            </geometry>
            <origin rpy="3.14 0 1.57" xyz="-.002 -.00375 .00375" />
            <material name="lightblue" />
        </visual>
        <collision>
            <geometry>
                <mesh filename="package://ar10_description/meshes/rod-end-2mm-BLUE.STL" scale=".001 .001 .001" />
            </geometry>
            <origin rpy="3.14 0 1.57" xyz="-.002 -.00375 .00375" />
        </collision>
        <inertial>
            <mass value="1" />
            <inertia ixx="0.4" ixy="0.0" ixz="0.0" iyy="0.4" iyz="0.0" izz="0.2" />
            <origin xyz="0 0 0" rpy="0 0 0" />
        </inertial>
    </link>
    <joint name="rb8_to_palm" type="fixed">
        <parent link="palm" />
        <child link="rb8" />
        <origin xyz="-.053 -.012 .095" />
    </joint>
    <link name="rb9">
        <visual>
            <geometry>
                <mesh filename="package://ar10_description/meshes/rod-end-2mm-BLUE.STL" scale=".001 .001 .001" />
            </geometry>
            <origin rpy="3.14 0 1.57" xyz="-.002 -.00375 .00375" />
            <material name="lightblue" />
        </visual>
        <collision>
            <geometry>
                <mesh filename="package://ar10_description/meshes/rod-end-2mm-BLUE.STL" scale=".001 .001 .001" />
            </geometry>
            <origin rpy="3.14 0 1.57" xyz="-.002 -.00375 .00375" />
        </collision>
        <inertial>
            <mass value="1" />
            <inertia ixx="0.4" ixy="0.0" ixz="0.0" iyy="0.4" iyz="0.0" izz="0.2" />
            <origin xyz="0 0 0" rpy="0 0 0" />
        </inertial>
    </link>
    <joint name="rb9_to_palm" type="fixed">
        <parent link="palm" />
        <child link="rb9" />
        <origin rpy="0 -1.29 0" xyz="-.039 -.012 .0295" />
    </joint>
    <link name="rb10">
        <visual>
            <geometry>
                <mesh filename="package://ar10_description/meshes/rod-end-2mm-BLUE.STL" scale=".001 .001 .001" />
            </geometry>
            <origin rpy="3.14 0 1.57" xyz="-.002 -.00375 .00375" />
            <material name="lightblue" />
        </visual>
        <collision>
            <geometry>
                <mesh filename="package://ar10_description/meshes/rod-end-2mm-BLUE.STL" scale=".001 .001 .001" />
            </geometry>
            <origin rpy="3.14 0 1.57" xyz="-.002 -.00375 .00375" />
        </collision>
        <inertial>
            <mass value="1" />
            <inertia ixx="0.4" ixy="0.0" ixz="0.0" iyy="0.4" iyz="0.0" izz="0.2" />
            <origin xyz="0 0 0" rpy="0 0 0" />
        </inertial>
    </link>
    <joint name="rb10_to_palm" type="fixed">
        <parent link="palm" />
        <child link="rb10" />
        <origin rpy="0 -1.29 0" xyz="-.041 -.012 .022" />
    </joint>
    <link name="rb11">
        <visual>
            <geometry>
                <mesh filename="package://ar10_description/meshes/rod-end-2mm-BLUE.STL" scale=".001 .001 .001" />
            </geometry>
            <origin rpy="3.14 1.57 1.57" xyz="-.002 .00375 .00375" />
            <material name="lightblue" />
        </visual>
        <collision>
            <geometry>
                <mesh filename="package://ar10_description/meshes/rod-end-2mm-BLUE.STL" scale=".001 .001 .001" />
            </geometry>
            <origin rpy="3.14 1.57 1.57" xyz="-.002 -.00375 .00375" />
        </collision>
        <inertial>
            <mass value="1" />
            <inertia ixx="0.4" ixy="0.0" ixz="0.0" iyy="0.4" iyz="0.0" izz="0.2" />
            <origin xyz="0 0 0" rpy="0 0 0" />
        </inertial>
    </link>
    <joint name="rb11_to_thumb2" type="fixed">
        <parent link="thumb2" />
        <child link="rb11" />
        <origin rpy=" 0 1.57 0" xyz="-.009 .0365 .0065" />
    </joint>
    <link name="rb12">
        <visual>
            <geometry>
                <mesh filename="package://ar10_description/meshes/rod-end-2mm-BLUE.STL" scale=".001 .001 .001" />
            </geometry>
            <origin rpy="3.14 1.57 1.57" xyz="-.002 .00375 .00375" />
            <material name="lightblue" />
        </visual>
        <collision>
            <geometry>
                <mesh filename="package://ar10_description/meshes/rod-end-2mm-BLUE.STL" scale=".001 .001 .001" />
            </geometry>
            <origin rpy="3.14 1.57 1.57" xyz="-.002 -.00375 .00375" />
        </collision>
        <inertial>
            <mass value="1" />
            <inertia ixx="0.4" ixy="0.0" ixz="0.0" iyy="0.4" iyz="0.0" izz="0.2" />
            <origin xyz="0 0 0" rpy="0 0 0" />
        </inertial>
    </link>
    <joint name="rb12_to_thumb2" type="fixed">
        <parent link="thumb2" />
        <child link="rb12" />
        <origin rpy=" 0 1.57 0" xyz="-.009 .0365 -.0065" />
    </joint>
    ****************Fingers A*******************************
    <link name="finger1.1a">
        <visual>
            <geometry>
                <mesh filename="package://ar10_description/meshes/45mm 3 hole.STL" scale=".001 .001 .001" />
            </geometry>
            <origin rpy="-1.57 1.57 0" xyz="0 -.00325 .0135" />
            <material name="blue" />
        </visual>
        <collision>
            <geometry>
                <mesh filename="package://ar10_description/meshes/45mm 3 hole.STL" scale=".001 .001 .001" />
            </geometry>
            <origin rpy="-1.57 1.57 0" xyz="0 -.00325 .0135" />
        </collision>
        <inertial>
            <mass value="1" />
            <inertia ixx="0.4" ixy="0.0" ixz="0.0" iyy="0.4" iyz="0.0" izz="0.2" />
            <origin xyz="0 0 0" rpy="0 0 0" />
        </inertial>
    </link>
    <joint name="servo2" type="revolute">
        <axis xyz="-1 0 0" />
        <limit effort="1000.0" lower="0.17" upper="1.57" velocity="0.5" />
        <parent link="rb1" />
        <child link="finger1.1a" />
        <origin rpy="3.14 0 0" xyz="-.002 0 0" />
        <joint_properties damping="1.0" friction="0.0" />
    </joint>
    <link name="finger1.2a">
        <visual>
            <geometry>
                <mesh filename="package://ar10_description/meshes/45mm 3 hole.STL" scale=".001 .001 .001" />
            </geometry>
            <origin rpy="-1.57 1.57 0" xyz="0 -.00325 .0135" />
            <material name="blue" />
        </visual>
        <collision>
            <geometry>
                <mesh filename="package://ar10_description/meshes/45mm 3 hole.STL" scale=".001 .001 .001" />
            </geometry>
            <origin rpy="-1.57 1.57 0" xyz="0 -.00325 .0135" />
        </collision>
        <inertial>
            <mass value="1" />
            <inertia ixx="0.4" ixy="0.0" ixz="0.0" iyy="0.4" iyz="0.0" izz="0.2" />
            <origin xyz="0 0 0" rpy="0 0 0" />
        </inertial>
    </link>
    <joint name="servo2m" type="revolute">
        <axis xyz="-1 0 0" />
        <limit effort="1000.0" lower="0.17" upper="1.57" velocity="0.5" />
        <parent link="rb2" />
        <child link="finger1.2a" />
        <origin rpy="3.14 0 0" xyz=".002 0 0" />
        <mimic joint="servo2" multiplier="1" offset="0" />
        <joint_properties damping="1.0" friction="0.0" />
    </joint>
    <link name="finger2.1a">
        <visual>
            <geometry>
                <mesh filename="package://ar10_description/meshes/45mm 3 hole.STL" scale=".001 .001 .001" />
            </geometry>
            <origin rpy="-1.57 1.57 0" xyz="0 -.00325 .0135" />
            <material name="blue" />
        </visual>
        <collision>
            <geometry>
                <mesh filename="package://ar10_description/meshes/45mm 3 hole.STL" scale=".001 .001 .001" />
            </geometry>
            <origin rpy="-1.57 1.57 0" xyz="0 -.00325 .0135" />
        </collision>
        <inertial>
            <mass value="1" />
            <inertia ixx="0.4" ixy="0.0" ixz="0.0" iyy="0.4" iyz="0.0" izz="0.2" />
            <origin xyz="0 0 0" rpy="0 0 0" />
        </inertial>
    </link>
    <joint name="servo4" type="revolute">
        <axis xyz="-1 0 0" />
        <limit effort="1000.0" lower="0.17" upper="1.57" velocity="0.5" />
        <parent link="rb3" />
        <child link="finger2.1a" />
        <origin rpy="3.14 0 0" xyz="-.002 0 0" />
        <joint_properties damping="1.0" friction="0.0" />
    </joint>
    <link name="finger2.2a">
        <visual>
            <geometry>
                <mesh filename="package://ar10_description/meshes/45mm 3 hole.STL" scale=".001 .001 .001" />
            </geometry>
            <origin rpy="-1.57 1.57 0" xyz="0 -.00325 .0135" />
            <material name="blue" />
        </visual>
        <collision>
            <geometry>
                <mesh filename="package://ar10_description/meshes/45mm 3 hole.STL" scale=".001 .001 .001" />
            </geometry>
            <origin rpy="-1.57 1.57 0" xyz="0 -.00325 .0135" />
        </collision>
        <inertial>
            <mass value="1" />
            <inertia ixx="0.4" ixy="0.0" ixz="0.0" iyy="0.4" iyz="0.0" izz="0.2" />
            <origin xyz="0 0 0" rpy="0 0 0" />
        </inertial>
    </link>
    <joint name="servo4m" type="revolute">
        <axis xyz="-1 0 0" />
        <limit effort="1000.0" lower="0.17" upper="1.57" velocity="0.5" />
        <parent link="rb4" />
        <child link="finger2.2a" />
        <origin rpy="3.14 0 0" xyz=".002 0 0" />
        <mimic joint="servo4" multiplier="1" offset="0" />
        <joint_properties damping="1.0" friction="0.0" />
    </joint>
    <link name="finger3.1a">
        <visual>
            <geometry>
                <mesh filename="package://ar10_description/meshes/45mm 3 hole.STL" scale=".001 .001 .001" />
            </geometry>
            <origin rpy="-1.57 1.57 0" xyz="0 -.00325 .0135" />
            <material name="blue" />
        </visual>
        <collision>
            <geometry>
                <mesh filename="package://ar10_description/meshes/45mm 3 hole.STL" scale=".001 .001 .001" />
            </geometry>
            <origin rpy="-1.57 1.57 0" xyz="0 -.00325 .0135" />
        </collision>
        <inertial>
            <mass value="1" />
            <inertia ixx="0.4" ixy="0.0" ixz="0.0" iyy="0.4" iyz="0.0" izz="0.2" />
            <origin xyz="0 0 0" rpy="0 0 0" />
        </inertial>
    </link>
    <joint name="servo6" type="revolute">
        <axis xyz="-1 0 0" />
        <limit effort="1000.0" lower="0.17" upper="1.57" velocity="0.5" />
        <parent link="rb5" />
        <child link="finger3.1a" />
        <origin rpy="3.14 0 0" xyz="-.002 0 0" />
        <joint_properties damping="1.0" friction="0.0" />
    </joint>
    <link name="finger3.2a">
        <visual>
            <geometry>
                <mesh filename="package://ar10_description/meshes/45mm 3 hole.STL" scale=".001 .001 .001" />
            </geometry>
            <origin rpy="-1.57 1.57 0" xyz="0 -.00325 .0135" />
            <material name="blue" />
        </visual>
        <collision>
            <geometry>
                <mesh filename="package://ar10_description/meshes/45mm 3 hole.STL" scale=".001 .001 .001" />
            </geometry>
            <origin rpy="-1.57 1.57 0" xyz="0 -.00325 .0135" />
        </collision>
        <inertial>
            <mass value="1" />
            <inertia ixx="0.4" ixy="0.0" ixz="0.0" iyy="0.4" iyz="0.0" izz="0.2" />
            <origin xyz="0 0 0" rpy="0 0 0" />
        </inertial>
    </link>
    <joint name="servo6m" type="revolute">
        <axis xyz="-1 0 0" />
        <limit effort="1000.0" lower="0.17" upper="1.57" velocity="0.5" />
        <parent link="rb6" />
        <child link="finger3.2a" />
        <origin rpy="3.14 0 0" xyz=".002 0 0" />
        <mimic joint="servo6" multiplier="1" offset="0" />
        <joint_properties damping="1.0" friction="0.0" />
    </joint>
    <link name="finger4.1a">
        <visual>
            <geometry>
                <mesh filename="package://ar10_description/meshes/45mm 3 hole.STL" scale=".001 .001 .001" />
            </geometry>
            <origin rpy="-1.57 1.57 0" xyz="0 -.00325 .0135" />
            <material name="blue" />
        </visual>
        <collision>
            <geometry>
                <mesh filename="package://ar10_description/meshes/45mm 3 hole.STL" scale=".001 .001 .001" />
            </geometry>
            <origin rpy="-1.57 1.57 0" xyz="0 -.00325 .0135" />
        </collision>
        <inertial>
            <mass value="1" />
            <inertia ixx="0.4" ixy="0.0" ixz="0.0" iyy="0.4" iyz="0.0" izz="0.2" />
            <origin xyz="0 0 0" rpy="0 0 0" />
        </inertial>
    </link>
    <joint name="servo8" type="revolute">
        <axis xyz="-1 0 0" />
        <limit effort="1000.0" lower="0.17" upper="1.57" velocity="0.5" />
        <parent link="rb7" />
        <child link="finger4.1a" />
        <origin rpy="3.14 0 0" xyz="-.002 0 0" />
        <joint_properties damping="1.0" friction="0.0" />
    </joint>
    <link name="finger4.2a">
        <visual>
            <geometry>
                <mesh filename="package://ar10_description/meshes/45mm 3 hole.STL" scale=".001 .001 .001" />
            </geometry>
            <origin rpy="-1.57 1.57 0" xyz="0 -.00325 .0135" />
            <material name="blue" />
        </visual>
        <collision>
            <geometry>
                <mesh filename="package://ar10_description/meshes/45mm 3 hole.STL" scale=".001 .001 .001" />
            </geometry>
            <origin rpy="-1.57 1.57 0" xyz="0 -.00325 .0135" />
        </collision>
        <inertial>
            <mass value="1" />
            <inertia ixx="0.4" ixy="0.0" ixz="0.0" iyy="0.4" iyz="0.0" izz="0.2" />
            <origin xyz="0 0 0" rpy="0 0 0" />
        </inertial>
    </link>
    <joint name="servo8m" type="revolute">
        <axis xyz="-1 0 0" />
        <limit effort="1000.0" lower="0.17" upper="1.57" velocity="0.5" />
        <parent link="rb8" />
        <child link="finger4.2a" />
        <origin rpy="3.14 0 0" xyz=".002 0 0" />
        <mimic joint="servo8" multiplier="1" offset="0" />
        <joint_properties damping="1.0" friction="0.0" />
    </joint>
    ****************Fingers B*******************************
    <link name="finger1.1b">
        <visual>
            <geometry>
                <mesh filename="package://ar10_description/meshes/30mmROSFULL.STL" scale=".001 .001 .001" />
            </geometry>
            <origin rpy="-1.57 1.57 0" xyz="0 -.0035 .0125" />
            <material name="blue" />
        </visual>
        <collision>
            <geometry>
                <mesh filename="package://ar10_description/meshes/30mmROSFULL.STL" scale=".001 .001 .001" />
            </geometry>
            <origin rpy="-1.57 1.57 0" xyz="0 -.0035 .0125" />
        </collision>
        <inertial>
            <mass value="1" />
            <inertia ixx="0.4" ixy="0.0" ixz="0.0" iyy="0.4" iyz="0.0" izz="0.2" />
            <origin xyz="0 0 0" rpy="0 0 0" />
        </inertial>
    </link>
    <joint name="servo3" type="revolute">
        <axis xyz="-1 0 0" />
        <limit effort="1000.0" lower="0.17" upper="1.57" velocity="0.5" />
        <parent link="finger1.1a" />
        <child link="finger1.1b" />
        <origin rpy="0 0 0" xyz=".001 0 -.045" />
        <joint_properties damping="1.0" friction="0.0" />
    </joint>
    <link name="finger1.2b">
        <visual>
            <geometry>
                <mesh filename="package://ar10_description/meshes/30mmROSFULL.STL" scale=".001 .001 .001" />
            </geometry>
            <origin rpy="-1.57 1.57 0" xyz="0 -.0035 .0125" />
            <material name="blue" />
        </visual>
        <collision>
            <geometry>
                <mesh filename="package://ar10_description/meshes/30mmROSFULL.STL" scale=".001 .001 .001" />
            </geometry>
            <origin rpy="-1.57 1.57 0" xyz="0 -.0035 .0125" />
        </collision>
        <inertial>
            <mass value="1" />
            <inertia ixx="0.4" ixy="0.0" ixz="0.0" iyy="0.4" iyz="0.0" izz="0.2" />
            <origin xyz="0 0 0" rpy="0 0 0" />
        </inertial>
    </link>
    <joint name="servo3m" type="revolute">
        <axis xyz="-1 0 0" />
        <limit effort="1000.0" lower="0.17" upper="1.57" velocity="0.5" />
        <parent link="finger1.2a" />
        <child link="finger1.2b" />
        <origin rpy="0 0 0" xyz="-.001 0 -.045" />
        <joint_properties damping="1.0" friction="0.0" />
        <mimic joint="servo3" multiplier="1" offset="0" />
    </joint>
    <link name="finger2.1b">
        <visual>
            <geometry>
                <mesh filename="package://ar10_description/meshes/30mmROSFULL.STL" scale=".001 .001 .001" />
            </geometry>
            <origin rpy="-1.57 1.57 0" xyz="0 -.0035 .0125" />
            <material name="blue" />
        </visual>
        <collision>
            <geometry>
                <mesh filename="package://ar10_description/meshes/30mmROSFULL.STL" scale=".001 .001 .001" />
            </geometry>
            <origin rpy="-1.57 1.57 0" xyz="0 -.0035 .0125" />
        </collision>
        <inertial>
            <mass value="1" />
            <inertia ixx="0.4" ixy="0.0" ixz="0.0" iyy="0.4" iyz="0.0" izz="0.2" />
            <origin xyz="0 0 0" rpy="0 0 0" />
        </inertial>
    </link>
    <joint name="servo5" type="revolute">
        <axis xyz="-1 0 0" />
        <limit effort="1000.0" lower="0.17" upper="1.57" velocity="0.5" />
        <parent link="finger2.1a" />
        <child link="finger2.1b" />
        <origin rpy="0 0 0" xyz=".001 0 -.045" />
        <joint_properties damping="1.0" friction="0.0" />
    </joint>
    <link name="finger2.2b">
        <visual>
            <geometry>
                <mesh filename="package://ar10_description/meshes/30mmROSFULL.STL" scale=".001 .001 .001" />
            </geometry>
            <origin rpy="-1.57 1.57 0" xyz="0 -.0035 .0125" />
            <material name="blue" />
        </visual>
        <collision>
            <geometry>
                <mesh filename="package://ar10_description/meshes/30mmROSFULL.STL" scale=".001 .001 .001" />
            </geometry>
            <origin rpy="-1.57 1.57 0" xyz="0 -.0035 .0125" />
        </collision>
        <inertial>
            <mass value="1" />
            <inertia ixx="0.4" ixy="0.0" ixz="0.0" iyy="0.4" iyz="0.0" izz="0.2" />
            <origin xyz="0 0 0" rpy="0 0 0" />
        </inertial>
    </link>
    <joint name="servo5m" type="revolute">
        <axis xyz="-1 0 0" />
        <limit effort="1000.0" lower="0.17" upper="1.57" velocity="0.5" />
        <parent link="finger2.2a" />
        <child link="finger2.2b" />
        <origin rpy="0 0 0" xyz="-.001 0 -.045" />
        <joint_properties damping="1.0" friction="0.0" />
        <mimic joint="servo5" multiplier="1" offset="0" />
    </joint>
    <link name="finger3.1b">
        <visual>
            <geometry>
                <mesh filename="package://ar10_description/meshes/30mmROSFULL.STL" scale=".001 .001 .001" />
            </geometry>
            <origin rpy="-1.57 1.57 0" xyz="0 -.0035 .0125" />
            <material name="blue" />
        </visual>
        <collision>
            <geometry>
                <mesh filename="package://ar10_description/meshes/30mmROSFULL.STL" scale=".001 .001 .001" />
            </geometry>
            <origin rpy="-1.57 1.57 0" xyz="0 -.0035 .0125" />
        </collision>
        <inertial>
            <mass value="1" />
            <inertia ixx="0.4" ixy="0.0" ixz="0.0" iyy="0.4" iyz="0.0" izz="0.2" />
            <origin xyz="0 0 0" rpy="0 0 0" />
        </inertial>
    </link>
    <joint name="servo7" type="revolute">
        <axis xyz="-1 0 0" />
        <limit effort="1000.0" lower="0.17" upper="1.57" velocity="0.5" />
        <parent link="finger3.1a" />
        <child link="finger3.1b" />
        <origin rpy="0 0 0" xyz=".001 0 -.045" />
        <joint_properties damping="1.0" friction="0.0" />
    </joint>
    <link name="finger3.2b">
        <visual>
            <geometry>
                <mesh filename="package://ar10_description/meshes/30mmROSFULL.STL" scale=".001 .001 .001" />
            </geometry>
            <origin rpy="-1.57 1.57 0" xyz="0 -.0035 .0125" />
            <material name="blue" />
        </visual>
        <collision>
            <geometry>
                <mesh filename="package://ar10_description/meshes/30mmROSFULL.STL" scale=".001 .001 .001" />
            </geometry>
            <origin rpy="-1.57 1.57 0" xyz="0 -.0035 .0125" />
        </collision>
        <inertial>
            <mass value="1" />
            <inertia ixx="0.4" ixy="0.0" ixz="0.0" iyy="0.4" iyz="0.0" izz="0.2" />
            <origin xyz="0 0 0" rpy="0 0 0" />
        </inertial>
    </link>
    <joint name="servo7m" type="revolute">
        <axis xyz="-1 0 0" />
        <limit effort="1000.0" lower="0.17" upper="1.57" velocity="0.5" />
        <parent link="finger3.2a" />
        <child link="finger3.2b" />
        <origin rpy="0 0 0" xyz="-.001 0 -.045" />
        <joint_properties damping="1.0" friction="0.0" />
        <mimic joint="servo7" multiplier="1" offset="0" />
    </joint>
    <link name="finger4.1b">
        <visual>
            <geometry>
                <mesh filename="package://ar10_description/meshes/30mmROSFULL.STL" scale=".001 .001 .001" />
            </geometry>
            <origin rpy="-1.57 1.57 0" xyz="0 -.0035 .0125" />
            <material name="blue" />
        </visual>
        <collision>
            <geometry>
                <mesh filename="package://ar10_description/meshes/30mmROSFULL.STL" scale=".001 .001 .001" />
            </geometry>
            <origin rpy="-1.57 1.57 0" xyz="0 -.0035 .0125" />
        </collision>
        <inertial>
            <mass value="1" />
            <inertia ixx="0.4" ixy="0.0" ixz="0.0" iyy="0.4" iyz="0.0" izz="0.2" />
            <origin xyz="0 0 0" rpy="0 0 0" />
        </inertial>
    </link>
    <joint name="servo9" type="revolute">
        <axis xyz="-1 0 0" />
        <limit effort="1000.0" lower="0.17" upper="1.57" velocity="0.5" />
        <parent link="finger4.1a" />
        <child link="finger4.1b" />
        <origin rpy="0 0 0" xyz=".001 0 -.045" />
        <joint_properties damping="1.0" friction="0.0" />
    </joint>
    <link name="finger4.2b">
        <visual>
            <geometry>
                <mesh filename="package://ar10_description/meshes/30mmROSFULL.STL" scale=".001 .001 .001" />
            </geometry>
            <origin rpy="-1.57 1.57 0" xyz="0 -.0035 .0125" />
            <material name="blue" />
        </visual>
        <collision>
            <geometry>
                <mesh filename="package://ar10_description/meshes/30mmROSFULL.STL" scale=".001 .001 .001" />
            </geometry>
            <origin rpy="-1.57 1.57 0" xyz="0 -.0035 .0125" />
        </collision>
        <inertial>
            <mass value="1" />
            <inertia ixx="0.4" ixy="0.0" ixz="0.0" iyy="0.4" iyz="0.0" izz="0.2" />
            <origin xyz="0 0 0" rpy="0 0 0" />
        </inertial>
    </link>
    <joint name="servo9m" type="revolute">
        <axis xyz="-1 0 0" />
        <limit effort="1000.0" lower="0.17" upper="1.57" velocity="0.5" />
        <parent link="finger4.2a" />
        <child link="finger4.2b" />
        <origin rpy="0 0 0" xyz="-.001 0 -.045" />
        <joint_properties damping="1.0" friction="0.0" />
        <mimic joint="servo9" multiplier="1" offset="0" />
    </joint>
    ****************Fingers C*******************************
    <link name="finger1.1c">
        <visual>
            <geometry>
                <mesh filename="package://ar10_description/meshes/Fingertip.STL" scale=".001 .001 .001" />
            </geometry>
            <origin rpy="-1.57 1.57 0" xyz="0 -.0035 .00825" />
            <material name="blue" />
        </visual>
        <collision>
            <geometry>
                <mesh filename="package://ar10_description/meshes/Fingertip.STL" scale=".001 .001 .001" />
            </geometry>
            <origin rpy="-1.57 1.57 0" xyz="0 -.0035 .00825" />
        </collision>
        <inertial>
            <mass value="1" />
            <inertia ixx="0.4" ixy="0.0" ixz="0.0" iyy="0.4" iyz="0.0" izz="0.2" />
            <origin xyz="0 0 0" rpy="0 0 0" />
        </inertial>
    </link>
    <joint name="tip1" type="revolute">
        <axis xyz="-1 0 0" />
        <limit effort="1000.0" lower="0.17" upper="1.57" velocity="0.5" />
        <parent link="finger1.1b" />
        <child link="finger1.1c" />
        <origin rpy="0 0 0" xyz="-.001 0 -.03" />
        <joint_properties damping="1.0" friction="0.0" />
        <mimic joint="servo3" multiplier=".49" offset=".16" />
    </joint>
    <link name="finger1.2c">
        <visual>
            <geometry>
                <mesh filename="package://ar10_description/meshes/Fingertip.STL" scale=".001 .001 .001" />
            </geometry>
            <origin rpy="-1.57 1.57 0" xyz="0 -.0035 .00825" />
            <material name="blue" />
        </visual>
        <collision>
            <geometry>
                <mesh filename="package://ar10_description/meshes/Fingertip.STL" scale=".001 .001 .001" />
            </geometry>
            <origin rpy="-1.57 1.57 0" xyz="0 -.0035 .00825" />
        </collision>
        <inertial>
            <mass value="1" />
            <inertia ixx="0.4" ixy="0.0" ixz="0.0" iyy="0.4" iyz="0.0" izz="0.2" />
            <origin xyz="0 0 0" rpy="0 0 0" />
        </inertial>
    </link>
    <joint name="tip1b" type="revolute">
        <axis xyz="-1 0 0" />
        <limit effort="1000.0" lower="0.17" upper="1.57" velocity="0.5" />
        <parent link="finger1.2b" />
        <child link="finger1.2c" />
        <origin rpy="0 0 0" xyz=".001 0 -.03" />
        <joint_properties damping="1.0" friction="0.0" />
        <mimic joint="servo3" multiplier=".49" offset=".16" />
    </joint>
    <link name="finger2.1c">
        <visual>
            <geometry>
                <mesh filename="package://ar10_description/meshes/Fingertip.STL" scale=".001 .001 .001" />
            </geometry>
            <origin rpy="-1.57 1.57 0" xyz="0 -.0035 .00825" />
            <material name="blue" />
        </visual>
        <collision>
            <geometry>
                <mesh filename="package://ar10_description/meshes/Fingertip.STL" scale=".001 .001 .001" />
            </geometry>
            <origin rpy="-1.57 1.57 0" xyz="0 -.0035 .00825" />
        </collision>
        <inertial>
            <mass value="1" />
            <inertia ixx="0.4" ixy="0.0" ixz="0.0" iyy="0.4" iyz="0.0" izz="0.2" />
            <origin xyz="0 0 0" rpy="0 0 0" />
        </inertial>
    </link>
    <joint name="tip2" type="revolute">
        <axis xyz="-1 0 0" />
        <limit effort="1000.0" lower="0.17" upper="1.57" velocity="0.5" />
        <parent link="finger2.1b" />
        <child link="finger2.1c" />
        <origin rpy="0 0 0" xyz="-.001 0 -.03" />
        <joint_properties damping="1.0" friction="0.0" />
        <mimic joint="servo5" multiplier=".49" offset=".16" />
    </joint>
    <link name="finger2.2c">
        <visual>
            <geometry>
                <mesh filename="package://ar10_description/meshes/Fingertip.STL" scale=".001 .001 .001" />
            </geometry>
            <origin rpy="-1.57 1.57 0" xyz="0 -.0035 .00825" />
            <material name="blue" />
        </visual>
        <collision>
            <geometry>
                <mesh filename="package://ar10_description/meshes/Fingertip.STL" scale=".001 .001 .001" />
            </geometry>
            <origin rpy="-1.57 1.57 0" xyz="0 -.0035 .00825" />
        </collision>
        <inertial>
            <mass value="1" />
            <inertia ixx="0.4" ixy="0.0" ixz="0.0" iyy="0.4" iyz="0.0" izz="0.2" />
            <origin xyz="0 0 0" rpy="0 0 0" />
        </inertial>
    </link>
    <joint name="tip2b" type="revolute">
        <axis xyz="-1 0 0" />
        <limit effort="1000.0" lower="0.17" upper="1.57" velocity="0.5" />
        <parent link="finger2.2b" />
        <child link="finger2.2c" />
        <origin rpy="0 0 0" xyz=".001 0 -.03" />
        <joint_properties damping="1.0" friction="0.0" />
        <mimic joint="servo5" multiplier=".49" offset=".16" />
    </joint>
    <link name="finger3.1c">
        <visual>
            <geometry>
                <mesh filename="package://ar10_description/meshes/Fingertip.STL" scale=".001 .001 .001" />
            </geometry>
            <origin rpy="-1.57 1.57 0" xyz="0 -.0035 .00825" />
            <material name="blue" />
        </visual>
        <collision>
            <geometry>
                <mesh filename="package://ar10_description/meshes/Fingertip.STL" scale=".001 .001 .001" />
            </geometry>
            <origin rpy="-1.57 1.57 0" xyz="0 -.0035 .00825" />
        </collision>
        <inertial>
            <mass value="1" />
            <inertia ixx="0.4" ixy="0.0" ixz="0.0" iyy="0.4" iyz="0.0" izz="0.2" />
            <origin xyz="0 0 0" rpy="0 0 0" />
        </inertial>
    </link>
    <joint name="tip3" type="revolute">
        <axis xyz="-1 0 0" />
        <limit effort="1000.0" lower="0.17" upper="1.57" velocity="0.5" />
        <parent link="finger3.1b" />
        <child link="finger3.1c" />
        <origin rpy="0 0 0" xyz="-.001 0 -.03" />
        <joint_properties damping="1.0" friction="0.0" />
        <mimic joint="servo7" multiplier=".49" offset=".16" />
    </joint>
    <link name="finger3.2c">
        <visual>
            <geometry>
                <mesh filename="package://ar10_description/meshes/Fingertip.STL" scale=".001 .001 .001" />
            </geometry>
            <origin rpy="-1.57 1.57 0" xyz="0 -.0035 .00825" />
            <material name="blue" />
        </visual>
        <collision>
            <geometry>
                <mesh filename="package://ar10_description/meshes/Fingertip.STL" scale=".001 .001 .001" />
            </geometry>
            <origin rpy="-1.57 1.57 0" xyz="0 -.0035 .00825" />
        </collision>
        <inertial>
            <mass value="1" />
            <inertia ixx="0.4" ixy="0.0" ixz="0.0" iyy="0.4" iyz="0.0" izz="0.2" />
            <origin xyz="0 0 0" rpy="0 0 0" />
        </inertial>
    </link>
    <joint name="tip3b" type="revolute">
        <axis xyz="-1 0 0" />
        <limit effort="1000.0" lower="0.17" upper="1.57" velocity="0.5" />
        <parent link="finger3.2b" />
        <child link="finger3.2c" />
        <origin rpy="0 0 0" xyz=".001 0 -.03" />
        <joint_properties damping="1.0" friction="0.0" />
        <mimic joint="servo7" multiplier=".49" offset=".16" />
    </joint>
    <link name="finger4.1c">
        <visual>
            <geometry>
                <mesh filename="package://ar10_description/meshes/Fingertip.STL" scale=".001 .001 .001" />
            </geometry>
            <origin rpy="-1.57 1.57 0" xyz="0 -.0035 .00825" />
            <material name="blue" />
        </visual>
        <collision>
            <geometry>
                <mesh filename="package://ar10_description/meshes/Fingertip.STL" scale=".001 .001 .001" />
            </geometry>
            <origin rpy="-1.57 1.57 0" xyz="0 -.0035 .00825" />
        </collision>
        <inertial>
            <mass value="1" />
            <inertia ixx="0.4" ixy="0.0" ixz="0.0" iyy="0.4" iyz="0.0" izz="0.2" />
            <origin xyz="0 0 0" rpy="0 0 0" />
        </inertial>
    </link>
    <joint name="tip4" type="revolute">
        <axis xyz="-1 0 0" />
        <limit effort="1000.0" lower="0.17" upper="1.57" velocity="0.5" />
        <parent link="finger4.1b" />
        <child link="finger4.1c" />
        <origin rpy="0 0 0" xyz="-.001 0 -.03" />
        <joint_properties damping="1.0" friction="0.0" />
        <mimic joint="servo9" multiplier=".49" offset=".16" />
    </joint>
    <link name="finger4.2c">
        <visual>
            <geometry>
                <mesh filename="package://ar10_description/meshes/Fingertip.STL" scale=".001 .001 .001" />
            </geometry>
            <origin rpy="-1.57 1.57 0" xyz="0 -.0035 .00825" />
            <material name="blue" />
        </visual>
        <collision>
            <geometry>
                <mesh filename="package://ar10_description/meshes/Fingertip.STL" scale=".001 .001 .001" />
            </geometry>
            <origin rpy="-1.57 1.57 0" xyz="0 -.0035 .00825" />
        </collision>
        <inertial>
            <mass value="1" />
            <inertia ixx="0.4" ixy="0.0" ixz="0.0" iyy="0.4" iyz="0.0" izz="0.2" />
            <origin xyz="0 0 0" rpy="0 0 0" />
        </inertial>
    </link>
    <joint name="tip4b" type="revolute">
        <axis xyz="-1 0 0" />
        <limit effort="1000.0" lower="0.17" upper="1.57" velocity="0.5" />
        <parent link="finger4.2b" />
        <child link="finger4.2c" />
        <origin rpy="0 0 0" xyz=".001 0 -.03" />
        <joint_properties damping="1.0" friction="0.0" />
        <mimic joint="servo9" multiplier=".49" offset=".16" />
    </joint>
    *********Finger Tips*************************
    <link name="fingertip1">
        <visual>
            <geometry>
                <mesh filename="package://ar10_description/meshes/fingertip-v9.STL" scale=".001 .001 .001" />
            </geometry>
            <origin rpy="1.57 0 0" xyz="-.009715 .011 -.015" />
            <material name="black" />
        </visual>
        <collision>
            <geometry>
                <box size=".015 .015 .03" />
            </geometry>
            <origin xyz="0 0 0" />
        </collision>
        <inertial>
            <mass value="1" />
            <inertia ixx="0.4" ixy="0.0" ixz="0.0" iyy="0.4" iyz="0.0" izz="0.2" />
            <origin xyz="0 0 0" rpy="0 0 0" />
        </inertial>
    </link>
    <joint name="ee1" type="fixed">
        <axis xyz="-1 0 0" />
        <limit effort="1000.0" lower="0.17" upper="1.57" velocity="0.5" />
        <parent link="finger1.1c" />
        <child link="fingertip1" />
        <origin rpy="0 0 0" xyz="-.005 0 -.02" />
    </joint>
    <link name="fingertip2">
        <visual>
            <geometry>
                <mesh filename="package://ar10_description/meshes/fingertip-v9.STL" scale=".001 .001 .001" />
            </geometry>
            <origin rpy="1.57 0 0" xyz="-.009715 .011 -.015" />
            <material name="black" />
        </visual>
        <collision>
            <geometry>
                <box size=".015 .015 .03" />
            </geometry>
            <origin xyz="0 0 0" />
        </collision>
        <inertial>
            <mass value="1" />
            <inertia ixx="0.4" ixy="0.0" ixz="0.0" iyy="0.4" iyz="0.0" izz="0.2" />
            <origin xyz="0 0 0" rpy="0 0 0" />
        </inertial>
    </link>
    <joint name="ee2" type="fixed">
        <axis xyz="-1 0 0" />
        <limit effort="1000.0" lower="0.17" upper="1.57" velocity="0.5" />
        <parent link="finger2.1c" />
        <child link="fingertip2" />
        <origin rpy="0 0 0" xyz="-.005 0 -.02" />
    </joint>
    <link name="fingertip3">
        <visual>
            <geometry>
                <mesh filename="package://ar10_description/meshes/fingertip-v9.STL" scale=".001 .001 .001" />
            </geometry>
            <origin rpy="1.57 0 0" xyz="-.009715 .011 -.015" />
            <material name="black" />
        </visual>
        <collision>
            <geometry>
                <box size=".015 .015 .03" />
            </geometry>
            <origin xyz="0 0 0" />
        </collision>
        <inertial>
            <mass value="1" />
            <inertia ixx="0.4" ixy="0.0" ixz="0.0" iyy="0.4" iyz="0.0" izz="0.2" />
            <origin xyz="0 0 0" rpy="0 0 0" />
        </inertial>
    </link>
    <joint name="ee3" type="fixed">
        <axis xyz="-1 0 0" />
        <limit effort="1000.0" lower="0.17" upper="1.57" velocity="0.5" />
        <parent link="finger3.1c" />
        <child link="fingertip3" />
        <origin rpy="0 0 0" xyz="-.005 0 -.02" />
    </joint>
    <link name="fingertip4">
        <visual>
            <geometry>
                <mesh filename="package://ar10_description/meshes/fingertip-v9.STL" scale=".001 .001 .001" />
            </geometry>
            <origin rpy="1.57 0 0" xyz="-.009715 .011 -.015" />
            <material name="black" />
        </visual>
        <collision>
            <geometry>
                <box size=".015 .015 .03" />
            </geometry>
            <origin xyz="0 0 0" />
        </collision>
        <inertial>
            <mass value="1" />
            <inertia ixx="0.4" ixy="0.0" ixz="0.0" iyy="0.4" iyz="0.0" izz="0.2" />
            <origin xyz="0 0 0" rpy="0 0 0" />
        </inertial>
    </link>
    <joint name="ee4" type="fixed">
        <axis xyz="-1 0 0" />
        <limit effort="1000.0" lower="0.17" upper="1.57" velocity="0.5" />
        <parent link="finger4.1c" />
        <child link="fingertip4" />
        <origin rpy="0 0 0" xyz="-.005 0 -.02" />
    </joint>
    **********************THUMB**************************************
    <link name="thumb1">
        <visual>
            <geometry>
                <mesh filename="package://ar10_description/meshes/Thumb 1.STL" scale=".001 .001 .001" />
            </geometry>
            <origin rpy="0 0 1.57" xyz="0 -.02125 -.00325" />
            <material name="blue" />
        </visual>
        <collision>
            <geometry>
                <mesh filename="package://ar10_description/meshes/Thumb 1.STL" scale=".001 .001 .001" />
            </geometry>
            <origin rpy="0 0 1.57" xyz="0 -.02125 -.00325" />
        </collision>
        <inertial>
            <mass value="1" />
            <inertia ixx="0.4" ixy="0.0" ixz="0.0" iyy="0.4" iyz="0.0" izz="0.2" />
            <origin xyz="0 0 0" rpy="0 0 0" />
        </inertial>
    </link>
    <joint name="servo0" type="revolute">
        <axis xyz="-1 0 0" />
        <limit effort="1000.0" lower="0.85" upper="2.15" velocity="0.5" />
        <parent link="rb10" />
        <child link="thumb1" />
        <origin rpy=" -1.57 0 0 " xyz="-.0015 0 0" />
        <joint_properties damping="1.0" friction="0.0" />
    </joint>
    <link name="thumb2">
        <visual>
            <geometry>
                <mesh filename="package://ar10_description/meshes/Thumb 2.STL" scale=".001 .001 .001" />
            </geometry>
            <origin rpy="0 0 1.57" xyz="0 -.0145 -.0095" />
            <material name="blue" />
        </visual>
        <collision>
            <geometry>
                <mesh filename="package://ar10_description/meshes/Thumb 2.STL" scale=".001 .001 .001" />
            </geometry>
            <origin rpy="0 0 1.57" xyz="0 -.0145 -.0095" />
        </collision>
        <inertial>
            <mass value="1" />
            <inertia ixx="0.4" ixy="0.0" ixz="0.0" iyy="0.4" iyz="0.0" izz="0.2" />
            <origin xyz="0 0 0" rpy="0 0 0" />
        </inertial>
    </link>
    <joint name="thumb2joint" type="fixed">
        <axis xyz="-1 0 0" />
        <limit effort="1000.0" lower="0.0" upper="1.5" velocity="0.5" />
        <parent link="thumb1" />
        <child link="thumb2" />
        <origin rpy=" 3.14 0 0 " xyz=".0068 0 0" />
        <joint_properties damping="1.0" friction="0.0" />
    </joint>
    <link name="thumb3.1">
        <visual>
            <geometry>
                <mesh filename="package://ar10_description/meshes/Thumb 3-Rev2.STL" scale=".001 .001 .001" />
            </geometry>
            <origin rpy="0 0 -1.57" xyz="0 .0125 -.0095" />
            <material name="blue" />
        </visual>
        <collision>
            <geometry>
                <mesh filename="package://ar10_description/meshes/Thumb 3-Rev2.STL" scale=".001 .001 .001" />
            </geometry>
            <origin rpy="0 0 -1.57" xyz="0 .0125 -.0095" />
        </collision>
        <inertial>
            <mass value="1" />
            <inertia ixx="0.4" ixy="0.0" ixz="0.0" iyy="0.4" iyz="0.0" izz="0.2" />
            <origin xyz="0 0 0" rpy="0 0 0" />
        </inertial>
    </link>
    <joint name="servo1" type="revolute">
        <axis xyz="1 0 0" />
        <limit effort="1000.0" lower="0.34" upper="1.5" velocity="0.5" />
        <parent link="rb11" />
        <child link="thumb3.1" />
        <origin rpy=" 3.14 0 0 " xyz=".002 0 0" />
        <joint_properties damping="1.0" friction="0.0" />
    </joint>
    <link name="thumb3.2">
        <visual>
            <geometry>
                <mesh filename="package://ar10_description/meshes/Thumb 3-Rev2.STL" scale=".001 .001 .001" />
            </geometry>
            <origin rpy="0 0 -1.57" xyz="0 .0125 -.0095" />
            <material name="blue" />
        </visual>
        <collision>
            <geometry>
                <mesh filename="package://ar10_description/meshes/Thumb 3-Rev2.STL" scale=".001 .001 .001" />
            </geometry>
            <origin rpy="0 0 -1.57" xyz="0 .0125 -.0095" />
        </collision>
        <inertial>
            <mass value="1" />
            <inertia ixx="0.4" ixy="0.0" ixz="0.0" iyy="0.4" iyz="0.0" izz="0.2" />
            <origin xyz="0 0 0" rpy="0 0 0" />
        </inertial>
    </link>
    <joint name="servo1m" type="revolute">
        <axis xyz="1 0 0" />
        <limit effort="1000.0" lower="0.0" upper="1.5" velocity="0.5" />
        <parent link="rb12" />
        <child link="thumb3.2" />
        <origin rpy=" 3.14 0 0 " xyz="-.002 0 0" />
        <joint_properties damping="1.0" friction="0.0" />
        <mimic joint="servo1" multiplier="1" offset="0" />
    </joint>
    <link name="thumbtip">
        <visual>
            <geometry>
                <mesh filename="package://ar10_description/meshes/fingertip-v9.STL" scale=".001 .001 .001" />
            </geometry>
            <origin rpy="2.55 3.14 0" xyz=".009715 .005 .005" />
            <material name="black" />
        </visual>
        <collision>
            <geometry>
                <box size=".015 .026 .015" />
            </geometry>
            <origin rpy="0.59 0 0" xyz="0 -.012 .01" />
        </collision>
        <inertial>
            <mass value="1" />
            <inertia ixx="0.4" ixy="0.0" ixz="0.0" iyy="0.4" iyz="0.0" izz="0.2" />
            <origin xyz="0 0 0" rpy="0 0 0" />
        </inertial>
    </link>
    <joint name="ee5" type="fixed">
        <axis xyz="1 0 0" />
        <limit effort="1000.0" lower="0.0" upper="1.5" velocity="0.5" />
        <parent link="thumb3.1" />
        <child link="thumbtip" />
        <origin rpy=" 3.14 0 0 " xyz=".0048575 -.055 0 " />
        <joint_properties damping="1.0" friction="0.0" />
    </joint>
    <transmission name="trans_panda_joint1">
        <type>transmission_interface/SimpleTransmission</type>
        <joint name="panda_joint1">
            <hardwareInterface>hardware_interface/EffortJointInterface</hardwareInterface>
        </joint>
        <actuator name="panda_joint1_motor">
            <hardwareInterface>hardware_interface/EffortJointInterface</hardwareInterface>
            <mechanicalReduction>1</mechanicalReduction>
        </actuator>
    </transmission>
    <transmission name="trans_panda_joint2">
        <type>transmission_interface/SimpleTransmission</type>
        <joint name="panda_joint2">
            <hardwareInterface>hardware_interface/EffortJointInterface</hardwareInterface>
        </joint>
        <actuator name="panda_joint2_motor">
            <hardwareInterface>hardware_interface/EffortJointInterface</hardwareInterface>
            <mechanicalReduction>1</mechanicalReduction>
        </actuator>
    </transmission>
    <transmission name="trans_panda_joint3">
        <type>transmission_interface/SimpleTransmission</type>
        <joint name="panda_joint3">
            <hardwareInterface>hardware_interface/EffortJointInterface</hardwareInterface>
        </joint>
        <actuator name="panda_joint3_motor">
            <hardwareInterface>hardware_interface/EffortJointInterface</hardwareInterface>
            <mechanicalReduction>1</mechanicalReduction>
        </actuator>
    </transmission>
    <transmission name="trans_panda_joint4">
        <type>transmission_interface/SimpleTransmission</type>
        <joint name="panda_joint4">
            <hardwareInterface>hardware_interface/EffortJointInterface</hardwareInterface>
        </joint>
        <actuator name="panda_joint4_motor">
            <hardwareInterface>hardware_interface/EffortJointInterface</hardwareInterface>
            <mechanicalReduction>1</mechanicalReduction>
        </actuator>
    </transmission>
    <transmission name="trans_panda_joint5">
        <type>transmission_interface/SimpleTransmission</type>
        <joint name="panda_joint5">
            <hardwareInterface>hardware_interface/EffortJointInterface</hardwareInterface>
        </joint>
        <actuator name="panda_joint5_motor">
            <hardwareInterface>hardware_interface/EffortJointInterface</hardwareInterface>
            <mechanicalReduction>1</mechanicalReduction>
        </actuator>
    </transmission>
    <transmission name="trans_panda_joint6">
        <type>transmission_interface/SimpleTransmission</type>
        <joint name="panda_joint6">
            <hardwareInterface>hardware_interface/EffortJointInterface</hardwareInterface>
        </joint>
        <actuator name="panda_joint6_motor">
            <hardwareInterface>hardware_interface/EffortJointInterface</hardwareInterface>
            <mechanicalReduction>1</mechanicalReduction>
        </actuator>
    </transmission>
    <transmission name="trans_panda_joint7">
        <type>transmission_interface/SimpleTransmission</type>
        <joint name="panda_joint7">
            <hardwareInterface>hardware_interface/EffortJointInterface</hardwareInterface>
        </joint>
        <actuator name="panda_joint7_motor">
            <hardwareInterface>hardware_interface/EffortJointInterface</hardwareInterface>
            <mechanicalReduction>1</mechanicalReduction>
        </actuator>
    </transmission>
    <transmission name="trans_servo2">
        <type>transmission_interface/SimpleTransmission</type>
        <joint name="servo2">
            <hardwareInterface>hardware_interface/EffortJointInterface</hardwareInterface>
        </joint>
        <actuator name="servo2_motor">
            <hardwareInterface>hardware_interface/EffortJointInterface</hardwareInterface>
            <mechanicalReduction>1</mechanicalReduction>
        </actuator>
    </transmission>
    <transmission name="trans_servo2m">
        <type>transmission_interface/SimpleTransmission</type>
        <joint name="servo2m">
            <hardwareInterface>hardware_interface/EffortJointInterface</hardwareInterface>
        </joint>
        <actuator name="servo2m_motor">
            <hardwareInterface>hardware_interface/EffortJointInterface</hardwareInterface>
            <mechanicalReduction>1</mechanicalReduction>
        </actuator>
    </transmission>
    <transmission name="trans_servo4">
        <type>transmission_interface/SimpleTransmission</type>
        <joint name="servo4">
            <hardwareInterface>hardware_interface/EffortJointInterface</hardwareInterface>
        </joint>
        <actuator name="servo4_motor">
            <hardwareInterface>hardware_interface/EffortJointInterface</hardwareInterface>
            <mechanicalReduction>1</mechanicalReduction>
        </actuator>
    </transmission>
    <transmission name="trans_servo4m">
        <type>transmission_interface/SimpleTransmission</type>
        <joint name="servo4m">
            <hardwareInterface>hardware_interface/EffortJointInterface</hardwareInterface>
        </joint>
        <actuator name="servo4m_motor">
            <hardwareInterface>hardware_interface/EffortJointInterface</hardwareInterface>
            <mechanicalReduction>1</mechanicalReduction>
        </actuator>
    </transmission>
    <transmission name="trans_servo6">
        <type>transmission_interface/SimpleTransmission</type>
        <joint name="servo6">
            <hardwareInterface>hardware_interface/EffortJointInterface</hardwareInterface>
        </joint>
        <actuator name="servo6_motor">
            <hardwareInterface>hardware_interface/EffortJointInterface</hardwareInterface>
            <mechanicalReduction>1</mechanicalReduction>
        </actuator>
    </transmission>
    <transmission name="trans_servo6m">
        <type>transmission_interface/SimpleTransmission</type>
        <joint name="servo6m">
            <hardwareInterface>hardware_interface/EffortJointInterface</hardwareInterface>
        </joint>
        <actuator name="servo6m_motor">
            <hardwareInterface>hardware_interface/EffortJointInterface</hardwareInterface>
            <mechanicalReduction>1</mechanicalReduction>
        </actuator>
    </transmission>
    <transmission name="trans_servo8">
        <type>transmission_interface/SimpleTransmission</type>
        <joint name="servo8">
            <hardwareInterface>hardware_interface/EffortJointInterface</hardwareInterface>
        </joint>
        <actuator name="servo8_motor">
            <hardwareInterface>hardware_interface/EffortJointInterface</hardwareInterface>
            <mechanicalReduction>1</mechanicalReduction>
        </actuator>
    </transmission>
    <transmission name="trans_servo8m">
        <type>transmission_interface/SimpleTransmission</type>
        <joint name="servo8m">
            <hardwareInterface>hardware_interface/EffortJointInterface</hardwareInterface>
        </joint>
        <actuator name="servo8m_motor">
            <hardwareInterface>hardware_interface/EffortJointInterface</hardwareInterface>
            <mechanicalReduction>1</mechanicalReduction>
        </actuator>
    </transmission>
    <transmission name="trans_servo3">
        <type>transmission_interface/SimpleTransmission</type>
        <joint name="servo3">
            <hardwareInterface>hardware_interface/EffortJointInterface</hardwareInterface>
        </joint>
        <actuator name="servo3_motor">
            <hardwareInterface>hardware_interface/EffortJointInterface</hardwareInterface>
            <mechanicalReduction>1</mechanicalReduction>
        </actuator>
    </transmission>
    <transmission name="trans_servo3m">
        <type>transmission_interface/SimpleTransmission</type>
        <joint name="servo3m">
            <hardwareInterface>hardware_interface/EffortJointInterface</hardwareInterface>
        </joint>
        <actuator name="servo3m_motor">
            <hardwareInterface>hardware_interface/EffortJointInterface</hardwareInterface>
            <mechanicalReduction>1</mechanicalReduction>
        </actuator>
    </transmission>
    <transmission name="trans_servo5">
        <type>transmission_interface/SimpleTransmission</type>
        <joint name="servo5">
            <hardwareInterface>hardware_interface/EffortJointInterface</hardwareInterface>
        </joint>
        <actuator name="servo5_motor">
            <hardwareInterface>hardware_interface/EffortJointInterface</hardwareInterface>
            <mechanicalReduction>1</mechanicalReduction>
        </actuator>
    </transmission>
    <transmission name="trans_servo5m">
        <type>transmission_interface/SimpleTransmission</type>
        <joint name="servo5m">
            <hardwareInterface>hardware_interface/EffortJointInterface</hardwareInterface>
        </joint>
        <actuator name="servo5m_motor">
            <hardwareInterface>hardware_interface/EffortJointInterface</hardwareInterface>
            <mechanicalReduction>1</mechanicalReduction>
        </actuator>
    </transmission>
    <transmission name="trans_servo7">
        <type>transmission_interface/SimpleTransmission</type>
        <joint name="servo7">
            <hardwareInterface>hardware_interface/EffortJointInterface</hardwareInterface>
        </joint>
        <actuator name="servo7_motor">
            <hardwareInterface>hardware_interface/EffortJointInterface</hardwareInterface>
            <mechanicalReduction>1</mechanicalReduction>
        </actuator>
    </transmission>
    <transmission name="trans_servo7m">
        <type>transmission_interface/SimpleTransmission</type>
        <joint name="servo7m">
            <hardwareInterface>hardware_interface/EffortJointInterface</hardwareInterface>
        </joint>
        <actuator name="servo7m_motor">
            <hardwareInterface>hardware_interface/EffortJointInterface</hardwareInterface>
            <mechanicalReduction>1</mechanicalReduction>
        </actuator>
    </transmission>
    <transmission name="trans_servo9">
        <type>transmission_interface/SimpleTransmission</type>
        <joint name="servo9">
            <hardwareInterface>hardware_interface/EffortJointInterface</hardwareInterface>
        </joint>
        <actuator name="servo9_motor">
            <hardwareInterface>hardware_interface/EffortJointInterface</hardwareInterface>
            <mechanicalReduction>1</mechanicalReduction>
        </actuator>
    </transmission>
    <transmission name="trans_servo9m">
        <type>transmission_interface/SimpleTransmission</type>
        <joint name="servo9m">
            <hardwareInterface>hardware_interface/EffortJointInterface</hardwareInterface>
        </joint>
        <actuator name="servo9m_motor">
            <hardwareInterface>hardware_interface/EffortJointInterface</hardwareInterface>
            <mechanicalReduction>1</mechanicalReduction>
        </actuator>
    </transmission>
    <transmission name="trans_tip1">
        <type>transmission_interface/SimpleTransmission</type>
        <joint name="tip1">
            <hardwareInterface>hardware_interface/EffortJointInterface</hardwareInterface>
        </joint>
        <actuator name="tip1_motor">
            <hardwareInterface>hardware_interface/EffortJointInterface</hardwareInterface>
            <mechanicalReduction>1</mechanicalReduction>
        </actuator>
    </transmission>
    <transmission name="trans_tip1b">
        <type>transmission_interface/SimpleTransmission</type>
        <joint name="tip1b">
            <hardwareInterface>hardware_interface/EffortJointInterface</hardwareInterface>
        </joint>
        <actuator name="tip1b_motor">
            <hardwareInterface>hardware_interface/EffortJointInterface</hardwareInterface>
            <mechanicalReduction>1</mechanicalReduction>
        </actuator>
    </transmission>
    <transmission name="trans_tip2">
        <type>transmission_interface/SimpleTransmission</type>
        <joint name="tip2">
            <hardwareInterface>hardware_interface/EffortJointInterface</hardwareInterface>
        </joint>
        <actuator name="tip2_motor">
            <hardwareInterface>hardware_interface/EffortJointInterface</hardwareInterface>
            <mechanicalReduction>1</mechanicalReduction>
        </actuator>
    </transmission>
    <transmission name="trans_tip2b">
        <type>transmission_interface/SimpleTransmission</type>
        <joint name="tip2b">
            <hardwareInterface>hardware_interface/EffortJointInterface</hardwareInterface>
        </joint>
        <actuator name="tip2b_motor">
            <hardwareInterface>hardware_interface/EffortJointInterface</hardwareInterface>
            <mechanicalReduction>1</mechanicalReduction>
        </actuator>
    </transmission>
    <transmission name="trans_tip3">
        <type>transmission_interface/SimpleTransmission</type>
        <joint name="tip3">
            <hardwareInterface>hardware_interface/EffortJointInterface</hardwareInterface>
        </joint>
        <actuator name="tip3_motor">
            <hardwareInterface>hardware_interface/EffortJointInterface</hardwareInterface>
            <mechanicalReduction>1</mechanicalReduction>
        </actuator>
    </transmission>
    <transmission name="trans_tip3b">
        <type>transmission_interface/SimpleTransmission</type>
        <joint name="tip3b">
            <hardwareInterface>hardware_interface/EffortJointInterface</hardwareInterface>
        </joint>
        <actuator name="tip3b_motor">
            <hardwareInterface>hardware_interface/EffortJointInterface</hardwareInterface>
            <mechanicalReduction>1</mechanicalReduction>
        </actuator>
    </transmission>
    <transmission name="trans_tip4">
        <type>transmission_interface/SimpleTransmission</type>
        <joint name="tip4">
            <hardwareInterface>hardware_interface/EffortJointInterface</hardwareInterface>
        </joint>
        <actuator name="tip4_motor">
            <hardwareInterface>hardware_interface/EffortJointInterface</hardwareInterface>
            <mechanicalReduction>1</mechanicalReduction>
        </actuator>
    </transmission>
    <transmission name="trans_tip4b">
        <type>transmission_interface/SimpleTransmission</type>
        <joint name="tip4b">
            <hardwareInterface>hardware_interface/EffortJointInterface</hardwareInterface>
        </joint>
        <actuator name="tip4b_motor">
            <hardwareInterface>hardware_interface/EffortJointInterface</hardwareInterface>
            <mechanicalReduction>1</mechanicalReduction>
        </actuator>
    </transmission>
    <transmission name="trans_servo0">
        <type>transmission_interface/SimpleTransmission</type>
        <joint name="servo0">
            <hardwareInterface>hardware_interface/EffortJointInterface</hardwareInterface>
        </joint>
        <actuator name="servo0_motor">
            <hardwareInterface>hardware_interface/EffortJointInterface</hardwareInterface>
            <mechanicalReduction>1</mechanicalReduction>
        </actuator>
    </transmission>
    <transmission name="trans_servo1">
        <type>transmission_interface/SimpleTransmission</type>
        <joint name="servo1">
            <hardwareInterface>hardware_interface/EffortJointInterface</hardwareInterface>
        </joint>
        <actuator name="servo1_motor">
            <hardwareInterface>hardware_interface/EffortJointInterface</hardwareInterface>
            <mechanicalReduction>1</mechanicalReduction>
        </actuator>
    </transmission>
    <transmission name="trans_servo1m">
        <type>transmission_interface/SimpleTransmission</type>
        <joint name="servo1m">
            <hardwareInterface>hardware_interface/EffortJointInterface</hardwareInterface>
        </joint>
        <actuator name="servo1m_motor">
            <hardwareInterface>hardware_interface/EffortJointInterface</hardwareInterface>
            <mechanicalReduction>1</mechanicalReduction>
        </actuator>
    </transmission>
    <gazebo>
        <plugin name="gazebo_ros_control">
            <robotNamespace>/</robotNamespace>
        </plugin>
    </gazebo>
</robot>

